Workbook
Name date: data_1!$D$2
Name Print_Area: '1.4 (1.4.1-1.4.2)'!$A$2:$BG$109
Name Print_Titles: '1.4 (1.4.1-1.4.2)'!$B:$C,'1.4 (1.4.1-1.4.2)'!$7:$12
Name ЕдиницаВыбор: Списки!$H$17:$H$19
Name ЕдиницаДоведение: #REF!
Name ЕдиницаМатрица: Списки!$H$17:$I$19
Name КОЛ01704: data_1!$Z$14:$Z$108
Name КОЛ01705: data_1!$AA$14:$AA$108
Name КОЛ01706: data_1!$AB$14:$AB$108
Name КОЛ01707: data_1!$AC$14:$AC$108
Name КОЛ01708: data_1!$AD$14:$AD$108
Name КОЛ01709: data_1!$AE$14:$AE$108
Name КОЛ01710: data_1!$AG$14:$AG$108
Name КОЛ01711: data_1!$AH$14:$AH$108
Name КОЛ01712: data_1!$AI$14:$AI$108
Name КОЛ01713: data_1!$AJ$14:$AJ$108
Name КОЛ01714: data_1!$AK$14:$AK$108
Name КОЛ01715: data_1!$AL$14:$AL$108
Name КОЛ01716: data_1!$AM$14:$AM$108
Name КОЛ01719: data_1!$AO$13:$AO$108
Name КОЛ01721: data_1!$AN$14:$AN$108
Name КОЛ01723: data_1!$AQ$14:$AQ$108
Name КОЛ01751: data_1!$AP$13:$AP$108
Name КОЛ01752: data_1!$AF$14:$AF$108
Name КОЛ04504: data_1!$DL$14:$DL$108
Name КОЛ04505: data_1!$DM$14:$DM$108
Name КОЛ04506: data_1!$DN$14:$DN$108
Name КОЛ04507: data_1!$DO$14:$DO$108
Name КОЛ04508: data_1!$DP$14:$DP$108
Name КОЛ04509: data_1!$DQ$14:$DQ$108
Name КОЛ04510: data_1!$DS$14:$DS$108
Name КОЛ04511: data_1!$DT$14:$DT$108
Name КОЛ04512: data_1!$DU$14:$DU$108
Name КОЛ04513: data_1!$DV$14:$DV$108
Name КОЛ04514: data_1!$DW$14:$DW$108
Name КОЛ04515: data_1!$DX$14:$DX$108
Name КОЛ04516: data_1!$DY$14:$DY$108
Name КОЛ04519: data_1!$EA$14:$EA$108
Name КОЛ04521: data_1!$DZ$14:$DZ$108
Name КОЛ04523: data_1!$EC$14:$EC$108
Name КОЛ04551: data_1!$EB$14:$EB$108
Name КОЛ04552: data_1!$DR$14:$DR$108
Name КОЛ04904: data_1!$GX$14:$GX$108
Name КОЛ04905: data_1!$GY$14:$GY$108
Name КОЛ04906: data_1!$GZ$14:$GZ$108
Name КОЛ04907: data_1!$HA$14:$HA$108
Name КОЛ04908: data_1!$HB$14:$HB$108
Name КОЛ04909: data_1!$HC$14:$HC$108
Name КОЛ04910: data_1!$HE$14:$HE$108
Name КОЛ04911: data_1!$HF$14:$HF$108
Name КОЛ04912: data_1!$HG$14:$HG$108
Name КОЛ04913: data_1!$HH$14:$HH$108
Name КОЛ04914: data_1!$HI$14:$HI$108
Name КОЛ04915: data_1!$HJ$14:$HJ$108
Name КОЛ04916: data_1!$HK$14:$HK$108
Name КОЛ04919: data_1!$HM$14:$HM$108
Name КОЛ04921: data_1!$HL$14:$HL$108
Name КОЛ04923: data_1!$HO$14:$HO$108
Name КОЛ04951: data_1!$HN$14:$HN$108
Name КОЛ04952: data_1!$HD$14:$HD$108

Sheet data_1
C2: по состояню на | D2: Декабрь 2017 г.
H5: 17 | Z5: КОЛ017 | AR5: 62 | BJ5: КОЛ062 | CB5: 37 | CT5: 45 | DL5: КОЛ045 | ED5: 75 | EV5: КОЛ075 | FN5: 61 | GF5: 49 | GX5: КОЛ049 | HD5: ё | HP5: 51 | IH5: КОЛ051 | IZ5: 52 | JR5: КОЛ052 | KJ5: 53 | LB5: КОЛ053 | LT5: 54 | ML5: КОЛ054 | ND5: 55 | NV5: КОЛ055 | ON5: 60 | PF5: КОЛ060 | PX5: 57
H6: 1.4 - Субсидии на возмещение части процентной ставки по инвестиционным кредитам (займам) на развитие растениеводства, переработки и развития инфраструктуры и логистического обеспечения рынков продукции растениеводства, КБК: 04 05 25Л0155440 523 | Z6: 1.4.Субсидии на возмещение части процентной ставки по инвестиционным кредитам (займам) в агропромышленном комплексе | AR6: 1.2- Субсидии на повышение продуктивности в молочном скотоводстве КБК: 04 05 25И0155420 521 | BJ6: 1.2- Субсидии на повышение продуктивности в молочном скотоводстве КБК: 04 05 25И015542F 521 | CB6: 1.1 - Субсидии на оказание несвязанной поддержки сельскохозяйственным товаропроизводителям в области растениеводства, КБК: 04 05 25И155410 523 | CT6: 1.3-Субсидии на содействие достижению целевых показателей региональных программ развития агропромышленного комплекса КБК: 04 05 25И0255430 523 | DL6: 1.3.Субсидии на содействие достижению целевых показателей региональных программ развития агропромышленного комплекса КБК: 04 05 25И025543F 523 | ED6: 1.5 - Субсидии на возмещение части прямых понесенных затрат на создание и модернизацию объектов селекционно-генетических центров в животноводстве и селекционно-семеноводческих центров в растениеводстве, а также на приобретение техники и оборудования на цели предоставления субсидий, КБК: 04 0525Л0255450 523 | EV6: 1.5.Субсидии на возмещение части прямых понесенных затрат на создание и модернизацию объектов агропромышленного комплекса, а также на приобретение техники и оборудования | FN6: 1.6-Субсидии на реализацию мероприятий федеральной целевой программы "Развитие мелиорации земель сельскохозяйственного назначения России на 2014 - 2020 годы" , КБК: 04 05 2580050760 521 | GF6: 2.1 - Субсидии на обеспечение жильем граждан, проживающих и работающих в сельской местности, и на обеспечение жильем молодых семей и молодых специалистов, проживающих и работающих в сельской местности, КБК: 10 03 2570050180 521 | GX6: 2.1 КБК 10 03 0000058000 521 | HP6: 2.2 - Софинансирование объектов капитального строительства госсобственности субъектов Российской Федерации (собственности муниципальных образований) всего, в том числе:, КБК: 05 02 2570050180 522 | IH6: 2.2.1 - Устойчивое развитие сельских территорий на 2014 - 2017 годы и на период до 2020 года" (ЖКХ), КБК: 05 02 0000058000 522 | IZ6: 2.2.2 - ФЦП "Устойчивое развитие сельских территорий на 2014 - 2017 годы и на период до 2020 года" (Образование), КБК: 07 02 2570050180 522 | JR6: 2.2.3 - ФЦП "Устойчивое развитие сельских территорий на 2014 - 2017 годы и на период до 2020 года" (Образование):, КБК: 07 02 0000058000 522 | KJ6: 2.2.4 -Устойчивое развитие сельских территорий на 2014 - 2017 годы и на период до 2020 года" (Медицина), КБК:09 02 2570050180 522 | LB6: 2.2.5 - Устойчивое развитие сельских территорий на 2014 - 2017 годы и на период до 2020 года" (Медицина):, КБК: 09 02 0000058000 522 | LT6: 2.2.6 - Устойчивое развитие сельских территорий на 2014 - 2017 годы и на период до 2020 года" (Спорт):, КБК: 11 01 2570050180 522 | ML6: 2.2.7 - Устойчивое развитие сельских территорий на 2014 - 2017 годы и на период до 2020 года" (Спорт):, КБК: 11 01 0000058000 522 | ND6: 2.3 - Субсидии на комплексную компактную застройку, КБК: 04 05 2570050180 522 | NV6: 2.3.1- Субсидии на комплексную компактную застройку, КБК: 04 05 0000058000 522 | ON6: 2.4. - Субсидии на грантовую поддержку местных инициатив граждан, проживающих в сельской местности, КБК: 04 05 2570050180 521 | PF6: 2.5. - Субсидии на грантовую поддержку местных инициатив граждан, проживающих в сельской местности, КБК:04 05 0000058000 521 | PX6: 3.-Целевые межбюджетные трансферты прошлых лет, полученные из федерального бюджета, КБК: 04 05 0000058000 521
F7: Предельный объем финансирования на текущую дату | G7: Остаток предельных объемов финансирования | H7: Остаток средств федерального бюджета на 01.01.2010 г., потребность в котором подтверждена | I7: Предусмотрено ср-в на т.г всего | J7: федерального бюджета | K7: бюджета субъекта Российской Федерации | L7: Получено из федерального бюджета в текущем году на отчетную дату | M7: Восстановлено средств федерального бюджета с начала т.г. по различным основаниям | N7: Подтверждение восстановления | O7: Пречислено на отчетную дату всего | P7: федерального бюджета | Q7: в т.с. За счет остатка | R7: бюджета субъекта Российской Федерации | S7: Фактический уровень финансирования | T7: Возвращено в федеральный бюджет в текущем году на отчетную дату | U7: Остаток средств ф.б на лиц. Счетах | V7: Кассовые расходы на текущую дату | W7: Прогноз остатков средств федерального бюджета на 31 декабря т.г. | X7: Лимит по распоряжению | Y7: Доведено РБС | Z7: Остаток средств федерального бюджета на 01.01.2010 г., потребность в котором подтверждена | AA7: Предусмотрено ср-в на т.г всего | AB7: федерального бюджета | AC7: бюджета субъекта Российской Федерации | AD7: Получено из федерального бюджета в текущем году на отчетную дату | AE7: Восстановлено средств федерального бюджета с начала т.г. по различным основаниям | AF7: Подтверждение восстановления | AG7: Пречислено на отчетную дату всего | AH7: федерального бюджета | AI7: в т.с. За счет остатка | AJ7: бюджета субъекта Российской Федерации | AK7: Фактический уровень финансирования | AL7: Возвращено в федеральный бюджет в текущем году на отчетную дату | AM7: Остаток средств ф.б на лиц. Счетах | AN7: Кассовые расходы на текущую дату | AO7: Прогноз остатков средств федерального бюджета на 31 декабря т.г. | AP7: Лимит по распоряжению | AQ7: Доведено РБС | AR7: Остаток средств федерального бюджета на 01.01.2010 г., потребность в котором подтверждена | AS7: Предусмотрено ср-в на т.г всего | AT7: федерального бюджета | AU7: бюджета субъекта Российской Федерации | AV7: Получено из федерального бюджета в текущем году на отчетную дату | AW7: Восстановлено средств федерального бюджета с начала т.г. по различным основаниям | AX7: Подтверждение восстановления | AY7: Пречислено на отчетную дату всего | AZ7: федерального бюджета | BA7: в т.с. За счет остатка | BB7: бюджета субъекта Российской Федерации | BC7: Фактический уровень финансирования | BD7: Возвращено в федеральный бюджет в текущем году на отчетную дату | BE7: Остаток средств ф.б на лиц. Счетах | BF7: Кассовые расходы на текущую дату | BG7: Прогноз остатков средств федерального бюджета на 31 декабря т.г. | BH7: Лимит по распоряжению | BI7: Доведено РБС | BJ7: Остаток средств федерального бюджета на 01.01.2010 г., потребность в котором подтверждена | BK7: Предусмотрено ср-в на т.г всего | BL7: федерального бюджета | BM7: бюджета субъекта Российской Федерации | BN7: Получено из федерального бюджета в текущем году на отчетную дату | BO7: Восстановлено средств федерального бюджета с начала т.г. по различным основаниям | BP7: Подтверждение восстановления | BQ7: Пречислено на отчетную дату всего | BR7: федерального бюджета | BS7: в т.с. За счет остатка | BT7: бюджета субъекта Российской Федерации | BU7: Фактический уровень финансирования | BV7: Возвращено в федеральный бюджет в текущем году на отчетную дату | BW7: Остаток средств ф.б на лиц. Счетах | BX7: Кассовые расходы на текущую дату | BY7: Прогноз остатков средств федерального бюджета на 31 декабря т.г. | BZ7: Лимит по распоряжению | CA7: Доведено РБС | CB7: Остаток средств федерального бюджета на 01.01.2010 г., потребность в котором подтверждена | CC7: Предусмотрено ср-в на т.г всего | CD7: федерального бюджета | CE7: бюджета субъекта Российской Федерации | CF7: Получено из федерального бюджета в текущем году на отчетную дату | CG7: Восстановлено средств федерального бюджета с начала т.г. по различным основаниям | CH7: Подтверждение восстановления | CI7: Пречислено на отчетную дату всего | CJ7: федерального бюджета | CK7: в т.с. За счет остатка | CL7: бюджета субъекта Российской Федерации | CM7: Фактический уровень финансирования | CN7: Возвращено в федеральный бюджет в текущем году на отчетную дату | CO7: Остаток средств ф.б на лиц. Счетах | CP7: Кассовые расходы на текущую дату | CQ7: Прогноз остатков средств федерального бюджета на 31 декабря т.г. | CR7: Лимит по распоряжению | CS7: Доведено РБС | CT7: Остаток средств федерального бюджета на 01.01.2010 г., потребность в котором подтверждена | CU7: Предусмотрено ср-в на т.г всего | CV7: федерального бюджета | CW7: бюджета субъекта Российской Федерации | CX7: Получено из федерального бюджета в текущем году на отчетную дату | CY7: Восстановлено средств федерального бюджета с начала т.г. по различным основаниям | CZ7: Подтверждение восстановления | DA7: Пречислено на отчетную дату всего | DB7: федерального бюджета | DC7: в т.с. За счет остатка | DD7: бюджета субъекта Российской Федерации | DE7: Фактический уровень финансирования | DF7: Возвращено в федеральный бюджет в текущем году на отчетную дату | DG7: Остаток средств ф.б на лиц. Счетах | DH7: Кассовые расходы на текущую дату | DI7: Прогноз остатков средств федерального бюджета на 31 декабря т.г. | DJ7: Лимит по распоряжению | DK7: Доведено РБС | DL7: Остаток средств федерального бюджета на 01.01.2010 г., потребность в котором подтверждена | DM7: Предусмотрено ср-в на т.г всего | DN7: федерального бюджета | DO7: бюджета субъекта Российской Федерации | DP7: Получено из федерального бюджета в текущем году на отчетную дату | DQ7: Восстановлено средств федерального бюджета с начала т.г. по различным основаниям | DR7: Подтверждение восстановления | DS7: Пречислено на отчетную дату всего | DT7: федерального бюджета | DU7: в т.с. За счет остатка | DV7: бюджета субъекта Российской Федерации | DW7: Фактический уровень финансирования | DX7: Возвращено в федеральный бюджет в текущем году на отчетную дату | DY7: Остаток средств ф.б на лиц. Счетах | DZ7: Кассовые расходы на текущую дату | EA7: Прогноз остатков средств федерального бюджета на 31 декабря т.г. | EB7: Лимит по распоряжению | EC7: Доведено РБС | ED7: Остаток средств федерального бюджета на 01.01.2010 г., потребность в котором подтверждена | EE7: Предусмотрено ср-в на т.г всего | EF7: федерального бюджета | EG7: бюджета субъекта Российской Федерации | EH7: Получено из федерального бюджета в текущем году на отчетную дату | EI7: Восстановлено средств федерального бюджета с начала т.г. по различным основаниям | EJ7: Подтверждение восстановления | EK7: Пречислено на отчетную дату всего | EL7: федерального бюджета | EM7: в т.с. За счет остатка | EN7: бюджета субъекта Российской Федерации | EO7: Фактический уровень финансирования | EP7: Возвращено в федеральный бюджет в текущем году на отчетную дату | EQ7: Остаток средств ф.б на лиц. Счетах | ER7: Кассовые расходы на текущую дату | ES7: Прогноз остатков средств федерального бюджета на 31 декабря т.г. | ET7: Лимит по распоряжению | EU7: Доведено РБС | EV7: Остаток средств федерального бюджета на 01.01.2010 г., потребность в котором подтверждена | EW7: Предусмотрено ср-в на т.г всего | EX7: федерального бюджета | EY7: бюджета субъекта Российской Федерации | EZ7: Получено из федерального бюджета в текущем году на отчетную дату | FA7: Восстановлено средств федерального бюджета с начала т.г. по различным основаниям | FB7: Подтверждение восстановления | FC7: Пречислено на отчетную дату всего | FD7: федерального бюджета | FE7: в т.с. За счет остатка | FF7: бюджета субъекта Российской Федерации | FG7: Фактический уровень финансирования | FH7: Возвращено в федеральный бюджет в текущем году на отчетную дату | FI7: Остаток средств ф.б на лиц. Счетах | FJ7: Кассовые расходы на текущую дату | FK7: Прогноз остатков средств федерального бюджета на 31 декабря т.г. | FL7: Лимит по распоряжению | FM7: Доведено РБС | FN7: Остаток средств федерального бюджета на 01.01.2010 г., потребность в котором подтверждена | FO7: Предусмотрено ср-в на т.г всего | FP7: федерального бюджета | FQ7: бюджета субъекта Российской Федерации | FR7: Получено из федерального бюджета в текущем году на отчетную дату | FS7: Восстановлено средств федерального бюджета с начала т.г. по различным основаниям | FT7: Подтверждение восстановления | FU7: Пречислено на отчетную дату всего | FV7: федерального бюджета | FW7: в т.с. За счет остатка | FX7: бюджета субъекта Российской Федерации | FY7: Фактический уровень финансирования | FZ7: Возвращено в федеральный бюджет в текущем году на отчетную дату | GA7: Остаток средств ф.б на лиц. Счетах | GB7: Кассовые расходы на текущую дату | GC7: Прогноз остатков средств федерального бюджета на 31 декабря т.г. | GD7: Лимит по распоряжению | GE7: Доведено РБС | GF7: Остаток средств федерального бюджета на 01.01.2010 г., потребность в котором подтверждена | GG7: Предусмотрено ср-в на т.г всего | GH7: федерального бюджета | GI7: бюджета субъекта Российской Федерации | GJ7: Получено из федерального бюджета в текущем году на отчетную дату | GK7: Восстановлено средств федерального бюджета с начала т.г. по различным основаниям | GL7: Подтверждение восстановления | GM7: Пречислено на отчетную дату всего | GN7: федерального бюджета | GO7: в т.с. За счет остатка | GP7: бюджета субъекта Российской Федерации | GQ7: Фактический уровень финансирования | GR7: Возвращено в федеральный бюджет в текущем году на отчетную дату | GS7: Остаток средств ф.б на лиц. Счетах | GT7: Кассовые расходы на текущую дату | GU7: Прогноз остатков средств федерального бюджета на 31 декабря т.г. | GV7: Лимит по распоряжению | GW7: Доведено РБС | GX7: Остаток средств федерального бюджета на 01.01.2010 г., потребность в котором подтверждена | GY7: Предусмотрено ср-в на т.г всего | GZ7: федерального бюджета | HA7: бюджета субъекта Российской Федерации | HB7: Получено из федерального бюджета в текущем году на отчетную дату | HC7: Восстановлено средств федерального бюджета с начала т.г. по различным основаниям | HD7: Подтверждение восстановления | HE7: Пречислено на отчетную дату всего | HF7: федерального бюджета | HG7: в т.с. За счет остатка | HH7: бюджета субъекта Российской Федерации | HI7: Фактический уровень финансирования | HJ7: Возвращено в федеральный бюджет в текущем году на отчетную дату | HK7: Остаток средств ф.б на лиц. Счетах | HL7: Кассовые расходы на текущую дату | HM7: Прогноз остатков средств федерального бюджета на 31 декабря т.г. | HN7: Лимит по распоряжению | HO7: Доведено РБС | HP7: Остаток средств федерального бюджета на 01.01.2010 г., потребность в котором подтверждена | HQ7: Предусмотрено ср-в на т.г всего | HR7: федерального бюджета | HS7: бюджета субъекта Российской Федерации | HT7: Получено из федерального бюджета в текущем году на отчетную дату | HU7: Восстановлено средств федерального бюджета с начала т.г. по различным основаниям | HV7: Подтверждение восстановления | HW7: Пречислено на отчетную дату всего | HX7: федерального бюджета | HY7: в т.с. За счет остатка | HZ7: бюджета субъекта Российской Федерации | IA7: Фактический уровень финансирования | IB7: Возвращено в федеральный бюджет в текущем году на отчетную дату | IC7: Остаток средств ф.б на лиц. Счетах | ID7: Кассовые расходы на текущую дату | IE7: Прогноз остатков средств федерального бюджета на 31 декабря т.г. | IF7: Лимит по распоряжению | IG7: Доведено РБС | IH7: Остаток средств федерального бюджета на 01.01.2010 г., потребность в котором подтверждена | II7: Предусмотрено ср-в на т.г всего | IJ7: федерального бюджета | IK7: бюджета субъекта Российской Федерации | IL7: Получено из федерального бюджета в текущем году на отчетную дату | IM7: Восстановлено средств федерального бюджета с начала т.г. по различным основаниям | IN7: Подтверждение восстановления | IO7: Пречислено на отчетную дату всего | IP7: федерального бюджета | IQ7: в т.с. За счет остатка | IR7: бюджета субъекта Российской Федерации | IS7: Фактический уровень финансирования | IT7: Возвращено в федеральный бюджет в текущем году на отчетную дату | IU7: Остаток средств ф.б на лиц. Счетах | IV7: Кассовые расходы на текущую дату | IW7: Прогноз остатков средств федерального бюджета на 31 декабря т.г. | IX7: Лимит по распоряжению | IY7: Доведено РБС | IZ7: Остаток средств федерального бюджета на 01.01.2010 г., потребность в котором подтверждена | JA7: Предусмотрено ср-в на т.г всего | JB7: федерального бюджета | JC7: бюджета субъекта Российской Федерации | JD7: Получено из федерального бюджета в текущем году на отчетную дату | JE7: Восстановлено средств федерального бюджета с начала т.г. по различным основаниям | JF7: Подтверждение восстановления | JG7: Пречислено на отчетную дату всего | JH7: федерального бюджета | JI7: в т.с. За счет остатка | JJ7: бюджета субъекта Российской Федерации | JK7: Фактический уровень финансирования | JL7: Возвращено в федеральный бюджет в текущем году на отчетную дату | JM7: Остаток средств ф.б на лиц. Счетах | JN7: Кассовые расходы на текущую дату | JO7: Прогноз остатков средств федерального бюджета на 31 декабря т.г. | JP7: Лимит по распоряжению | JQ7: Доведено РБС | JR7: Остаток средств федерального бюджета на 01.01.2010 г., потребность в котором подтверждена | JS7: Предусмотрено ср-в на т.г всего | JT7: федерального бюджета | JU7: бюджета субъекта Российской Федерации | JV7: Получено из федерального бюджета в текущем году на отчетную дату | JW7: Восстановлено средств федерального бюджета с начала т.г. по различным основаниям | JX7: Подтверждение восстановления | JY7: Пречислено на отчетную дату всего | JZ7: федерального бюджета | KA7: в т.с. За счет остатка | KB7: бюджета субъекта Российской Федерации | KC7: Фактический уровень финансирования | KD7: Возвращено в федеральный бюджет в текущем году на отчетную дату | KE7: Остаток средств ф.б на лиц. Счетах | KF7: Кассовые расходы на текущую дату | KG7: Прогноз остатков средств федерального бюджета на 31 декабря т.г. | KH7: Лимит по распоряжению | KI7: Доведено РБС | KJ7: Остаток средств федерального бюджета на 01.01.2010 г., потребность в котором подтверждена | KK7: Предусмотрено ср-в на т.г всего | KL7: федерального бюджета | KM7: бюджета субъекта Российской Федерации | KN7: Получено из федерального бюджета в текущем году на отчетную дату | KO7: Восстановлено средств федерального бюджета с начала т.г. по различным основаниям | KP7: Подтверждение восстановления | KQ7: Пречислено на отчетную дату всего | KR7: федерального бюджета | KS7: в т.с. За счет остатка | KT7: бюджета субъекта Российской Федерации | KU7: Фактический уровень финансирования | KV7: Возвращено в федеральный бюджет в текущем году на отчетную дату | KW7: Остаток средств ф.б на лиц. Счетах | KX7: Кассовые расходы на текущую дату | KY7: Прогноз остатков средств федерального бюджета на 31 декабря т.г. | KZ7: Лимит по распоряжению | LA7: Доведено РБС | LB7: Остаток средств федерального бюджета на 01.01.2010 г., потребность в котором подтверждена | LC7: Предусмотрено ср-в на т.г всего | LD7: федерального бюджета | LE7: бюджета субъекта Российской Федерации | LF7: Получено из федерального бюджета в текущем году на отчетную дату | LG7: Восстановлено средств федерального бюджета с начала т.г. по различным основаниям | LH7: Подтверждение восстановления | LI7: Пречислено на отчетную дату всего | LJ7: федерального бюджета | LK7: в т.с. За счет остатка | LL7: бюджета субъекта Российской Федерации | LM7: Фактический уровень финансирования | LN7: Возвращено в федеральный бюджет в текущем году на отчетную дату | LO7: Остаток средств ф.б на лиц. Счетах | LP7: Кассовые расходы на текущую дату | LQ7: Прогноз остатков средств федерального бюджета на 31 декабря т.г. | LR7: Лимит по распоряжению | LS7: Доведено РБС | LT7: Остаток средств федерального бюджета на 01.01.2010 г., потребность в котором подтверждена | LU7: Предусмотрено ср-в на т.г всего | LV7: федерального бюджета | LW7: бюджета субъекта Российской Федерации | LX7: Получено из федерального бюджета в текущем году на отчетную дату | LY7: Восстановлено средств федерального бюджета с начала т.г. по различным основаниям | LZ7: Подтверждение восстановления | MA7: Пречислено на отчетную дату всего | MB7: федерального бюджета | MC7: в т.с. За счет остатка | MD7: бюджета субъекта Российской Федерации | ME7: Фактический уровень финансирования | MF7: Возвращено в федеральный бюджет в текущем году на отчетную дату | MG7: Остаток средств ф.б на лиц. Счетах | MH7: Кассовые расходы на текущую дату | MI7: Прогноз остатков средств федерального бюджета на 31 декабря т.г. | MJ7: Лимит по распоряжению | MK7: Доведено РБС | ML7: Остаток средств федерального бюджета на 01.01.2010 г., потребность в котором подтверждена | MM7: Предусмотрено ср-в на т.г всего | MN7: федерального бюджета | MO7: бюджета субъекта Российской Федерации | MP7: Получено из федерального бюджета в текущем году на отчетную дату | MQ7: Восстановлено средств федерального бюджета с начала т.г. по различным основаниям | MR7: Подтверждение восстановления | MS7: Пречислено на отчетную дату всего | MT7: федерального бюджета | MU7: в т.с. За счет остатка | MV7: бюджета субъекта Российской Федерации | MW7: Фактический уровень финансирования | MX7: Возвращено в федеральный бюджет в текущем году на отчетную дату | MY7: Остаток средств ф.б на лиц. Счетах | MZ7: Кассовые расходы на текущую дату | NA7: Прогноз остатков средств федерального бюджета на 31 декабря т.г. | NB7: Лимит по распоряжению | NC7: Доведено РБС | ND7: Остаток средств федерального бюджета на 01.01.2010 г., потребность в котором подтверждена | NE7: Предусмотрено ср-в на т.г всего | NF7: федерального бюджета | NG7: бюджета субъекта Российской Федерации | NH7: Получено из федерального бюджета в текущем году на отчетную дату | NI7: Восстановлено средств федерального бюджета с начала т.г. по различным основаниям | NJ7: Подтверждение восстановления | NK7: Пречислено на отчетную дату всего | NL7: федерального бюджета | NM7: в т.с. За счет остатка | NN7: бюджета субъекта Российской Федерации | NO7: Фактический уровень финансирования | NP7: Возвращено в федеральный бюджет в текущем году на отчетную дату | NQ7: Остаток средств ф.б на лиц. Счетах | NR7: Кассовые расходы на текущую дату | NS7: Прогноз остатков средств федерального бюджета на 31 декабря т.г. | NT7: Лимит по распоряжению | NU7: Доведено РБС | NV7: Остаток средств федерального бюджета на 01.01.2010 г., потребность в котором подтверждена | NW7: Предусмотрено ср-в на т.г всего | NX7: федерального бюджета | NY7: бюджета субъекта Российской Федерации | NZ7: Получено из федерального бюджета в текущем году на отчетную дату | OA7: Восстановлено средств федерального бюджета с начала т.г. по различным основаниям | OB7: Подтверждение восстановления | OC7: Пречислено на отчетную дату всего | OD7: федерального бюджета | OE7: в т.с. За счет остатка | OF7: бюджета субъекта Российской Федерации | OG7: Фактический уровень финансирования | OH7: Возвращено в федеральный бюджет в текущем году на отчетную дату | OI7: Остаток средств ф.б на лиц. Счетах | OJ7: Кассовые расходы на текущую дату | OK7: Прогноз остатков средств федерального бюджета на 31 декабря т.г. | OL7: Лимит по распоряжению | OM7: Доведено РБС | ON7: Остаток средств федерального бюджета на 01.01.2010 г., потребность в котором подтверждена | OO7: Предусмотрено ср-в на т.г всего | OP7: федерального бюджета | OQ7: бюджета субъекта Российской Федерации | OR7: Получено из федерального бюджета в текущем году на отчетную дату | OS7: Восстановлено средств федерального бюджета с начала т.г. по различным основаниям | OT7: Подтверждение восстановления | OU7: Пречислено на отчетную дату всего | OV7: федерального бюджета | OW7: в т.с. За счет остатка | OX7: бюджета субъекта Российской Федерации | OY7: Фактический уровень финансирования | OZ7: Возвращено в федеральный бюджет в текущем году на отчетную дату | PA7: Остаток средств ф.б на лиц. Счетах | PB7: Кассовые расходы на текущую дату | PC7: Прогноз остатков средств федерального бюджета на 31 декабря т.г. | PD7: Лимит по распоряжению | PE7: Доведено РБС | PF7: Остаток средств федерального бюджета на 01.01.2010 г., потребность в котором подтверждена | PG7: Предусмотрено ср-в на т.г всего | PH7: федерального бюджета | PI7: бюджета субъекта Российской Федерации | PJ7: Получено из федерального бюджета в текущем году на отчетную дату | PK7: Восстановлено средств федерального бюджета с начала т.г. по различным основаниям | PL7: Подтверждение восстановления | PM7: Пречислено на отчетную дату всего | PN7: федерального бюджета | PO7: в т.с. За счет остатка | PP7: бюджета субъекта Российской Федерации | PQ7: Фактический уровень финансирования | PR7: Возвращено в федеральный бюджет в текущем году на отчетную дату | PS7: Остаток средств ф.б на лиц. Счетах | PT7: Кассовые расходы на текущую дату | PU7: Прогноз остатков средств федерального бюджета на 31 декабря т.г. | PV7: Лимит по распоряжению | PW7: Доведено РБС | PX7: Остаток средств федерального бюджета на 01.01.2010 г., потребность в котором подтверждена | PY7: Предусмотрено ср-в на т.г всего | PZ7: федерального бюджета | QA7: бюджета субъекта Российской Федерации | QB7: Получено из федерального бюджета в текущем году на отчетную дату | QC7: Восстановлено средств федерального бюджета с начала т.г. по различным основаниям | QD7: Подтверждение восстановления | QE7: Пречислено на отчетную дату всего | QF7: федерального бюджета | QG7: в т.с. За счет остатка | QH7: бюджета субъекта Российской Федерации | QI7: Фактический уровень финансирования | QJ7: Возвращено в федеральный бюджет в текущем году на отчетную дату | QK7: Остаток средств ф.б на лиц. Счетах | QL7: Кассовые расходы на текущую дату | QM7: Прогноз остатков средств федерального бюджета на 31 декабря т.г. | QN7: Лимит по распоряжению | QO7: Доведено РБС
D13: 37776П | E13: 37776К | F13: 1020 | G13: 1022 | H13: =H5&"04" -> 1704 | I13: =H5&"05" -> 1705 | J13: =H5&"06" -> 1706 | K13: =H5&"07" -> 1707 | L13: =H5&"08" -> 1708 | M13: =H5&"09" -> 1709 | N13: =H5&"52" -> 1752 | O13: =H5&"10" -> 1710 | P13: =H5&"11" -> 1711 | Q13: =H5&"12" -> 1712 | R13: =H5&"13" -> 1713 | S13: =H5&"14" -> 1714 | T13: =H5&"15" -> 1715 | U13: =H5&"16" -> 1716 | V13: =H5&"21" -> 1721 | W13: =H5&"19" -> 1719 | X13: =H5&"51" -> 1751 | Y13: =H5&"23" -> 1723 | Z13: =Z5&"04" -> КОЛ01704 | AA13: =Z5&"05" -> КОЛ01705 | AB13: =Z5&"06" -> КОЛ01706 | AC13: =Z5&"07" -> КОЛ01707 | AD13: =Z5&"08" -> КОЛ01708 | AE13: =Z5&"09" -> КОЛ01709 | AF13: =Z5&"52" -> КОЛ01752 | AG13: =Z5&"10" -> КОЛ01710 | AH13: =Z5&"11" -> КОЛ01711 | AI13: =Z5&"12" -> КОЛ01712 | AJ13: =Z5&"13" -> КОЛ01713 | AK13: =Z5&"14" -> КОЛ01714 | AL13: =Z5&"15" -> КОЛ01715 | AM13: =Z5&"16" -> КОЛ01716 | AN13: =Z5&"21" -> КОЛ01721 | AO13: =Z5&"19" -> КОЛ01719 | AP13: =Z5&"51" -> КОЛ01751 | AQ13: =Z5&"23" -> КОЛ01723 | AR13: =AR5&"04" -> 6204 | AS13: =AR5&"05" -> 6205 | AT13: =AR5&"06" -> 6206 | AU13: =AR5&"07" -> 6207 | AV13: =AR5&"08" -> 6208 | AW13: =AR5&"09" -> 6209 | AX13: =AR5&"52" -> 6252 | AY13: =AR5&"10" -> 6210 | AZ13: =AR5&"11" -> 6211 | BA13: =AR5&"12" -> 6212 | BB13: =AR5&"13" -> 6213 | BC13: =AR5&"14" -> 6214 | BD13: =AR5&"15" -> 6215 | BE13: =AR5&"16" -> 6216 | BF13: =AR5&"21" -> 6221 | BG13: =AR5&"19" -> 6219 | BH13: =AR5&"51" -> 6251 | BI13: =AR5&"23" -> 6223 | BJ13: =BJ5&"04" -> КОЛ06204 | BK13: =BJ5&"05" -> КОЛ06205 | BL13: =BJ5&"06" -> КОЛ06206 | BM13: =BJ5&"07" -> КОЛ06207 | BN13: =BJ5&"08" -> КОЛ06208 | BO13: =BJ5&"09" -> КОЛ06209 | BP13: =BJ5&"52" -> КОЛ06252 | BQ13: =BJ5&"10" -> КОЛ06210 | BR13: =BJ5&"11" -> КОЛ06211 | BS13: =BJ5&"12" -> КОЛ06212 | BT13: =BJ5&"13" -> КОЛ06213 | BU13: =BJ5&"14" -> КОЛ06214 | BV13: =BJ5&"15" -> КОЛ06215 | BW13: =BJ5&"16" -> КОЛ06216 | BX13: =BJ5&"21" -> КОЛ06221 | BY13: =BJ5&"19" -> КОЛ06219 | BZ13: =BJ5&"51" -> КОЛ06251 | CA13: =BJ5&"23" -> КОЛ06223 | CB13: =CB5&"04" -> 3704 | CC13: =CB5&"05" -> 3705 | CD13: =CB5&"06" -> 3706 | CE13: =CB5&"07" -> 3707 | CF13: =CB5&"08" -> 3708 | CG13: =CB5&"09" -> 3709 | CH13: =CB5&"52" -> 3752 | CI13: =CB5&"10" -> 3710 | CJ13: =CB5&"11" -> 3711 | CK13: =CB5&"12" -> 3712 | CL13: =CB5&"13" -> 3713 | CM13: =CB5&"14" -> 3714 | CN13: =CB5&"15" -> 3715 | CO13: =CB5&"16" -> 3716 | CP13: =CB5&"21" -> 3721 | CQ13: =CB5&"19" -> 3719 | CR13: =CB5&"51" -> 3751 | CS13: =CB5&"23" -> 3723 | CT13: =CT5&"04" -> 4504 | CU13: =CT5&"05" -> 4505 | CV13: =CT5&"06" -> 4506 | CW13: =CT5&"07" -> 4507 | CX13: =CT5&"08" -> 4508 | CY13: =CT5&"09" -> 4509 | CZ13: =CT5&"52" -> 4552 | DA13: =CT5&"10" -> 4510 | DB13: =CT5&"11" -> 4511 | DC13: =CT5&"12" -> 4512 | DD13: =CT5&"13" -> 4513 | DE13: =CT5&"14" -> 4514 | DF13: =CT5&"15" -> 4515 | DG13: =CT5&"16" -> 4516 | DH13: =CT5&"21" -> 4521 | DI13: =CT5&"19" -> 4519 | DJ13: =CT5&"51" -> 4551 | DK13: =CT5&"23" -> 4523 | DL13: =DL5&"04" -> КОЛ04504 | DM13: =DL5&"05" -> КОЛ04505 | DN13: =DL5&"06" -> КОЛ04506 | DO13: =DL5&"07" -> КОЛ04507 | DP13: =DL5&"08" -> КОЛ04508 | DQ13: =DL5&"09" -> КОЛ04509 | DR13: =DL5&"52" -> КОЛ04552 | DS13: =DL5&"10" -> КОЛ04510 | DT13: =DL5&"11" -> КОЛ04511 | DU13: =DL5&"12" -> КОЛ04512 | DV13: =DL5&"13" -> КОЛ04513 | DW13: =DL5&"14" -> КОЛ04514 | DX13: =DL5&"15" -> КОЛ04515 | DY13: =DL5&"16" -> КОЛ04516 | DZ13: =DL5&"21" -> КОЛ04521 | EA13: =DL5&"19" -> КОЛ04519 | EB13: =DL5&"51" -> КОЛ04551 | EC13: =DL5&"23" -> КОЛ04523 | ED13: =ED5&"04" -> 7504 | EE13: =ED5&"05" -> 7505 | EF13: =ED5&"06" -> 7506 | EG13: =ED5&"07" -> 7507 | EH13: =ED5&"08" -> 7508 | EI13: =ED5&"09" -> 7509 | EJ13: =ED5&"52" -> 7552 | EK13: =ED5&"10" -> 7510 | EL13: =ED5&"11" -> 7511 | EM13: =ED5&"12" -> 7512 | EN13: =ED5&"13" -> 7513 | EO13: =ED5&"14" -> 7514 | EP13: =ED5&"15" -> 7515 | EQ13: =ED5&"16" -> 7516 | ER13: =ED5&"21" -> 7521 | ES13: =ED5&"19" -> 7519 | ET13: =ED5&"51" -> 7551 | EU13: =ED5&"23" -> 7523 | EV13: =EV5&"04" -> КОЛ07504 | EW13: =EV5&"05" -> КОЛ07505 | EX13: =EV5&"06" -> КОЛ07506 | EY13: =EV5&"07" -> КОЛ07507 | EZ13: =EV5&"08" -> КОЛ07508 | FA13: =EV5&"09" -> КОЛ07509 | FB13: =EV5&"52" -> КОЛ07552 | FC13: =EV5&"10" -> КОЛ07510 | FD13: =EV5&"11" -> КОЛ07511 | FE13: =EV5&"12" -> КОЛ07512 | FF13: =EV5&"13" -> КОЛ07513 | FG13: =EV5&"14" -> КОЛ07514 | FH13: =EV5&"15" -> КОЛ07515 | FI13: =EV5&"16" -> КОЛ07516 | FJ13: =EV5&"21" -> КОЛ07521 | FK13: =EV5&"19" -> КОЛ07519 | FL13: =EV5&"51" -> КОЛ07551 | FM13: =EV5&"23" -> КОЛ07523 | FN13: =FN5&"04" -> 6104 | FO13: =FN5&"05" -> 6105 | FP13: =FN5&"06" -> 6106 | FQ13: =FN5&"07" -> 6107 | FR13: =FN5&"08" -> 6108 | FS13: =FN5&"09" -> 6109 | FT13: =FN5&"52" -> 6152 | FU13: =FN5&"10" -> 6110 | FV13: =FN5&"11" -> 6111 | FW13: =FN5&"12" -> 6112 | FX13: =FN5&"13" -> 6113 | FY13: =FN5&"14" -> 6114 | FZ13: =FN5&"15" -> 6115 | GA13: =FN5&"16" -> 6116 | GB13: =FN5&"21" -> 6121 | GC13: =FN5&"19" -> 6119 | GD13: =FN5&"51" -> 6151 | GE13: =FN5&"23" -> 6123 | GF13: =GF5&"04" -> 4904 | GG13: =GF5&"05" -> 4905 | GH13: =GF5&"06" -> 4906 | GI13: =GF5&"07" -> 4907 | GJ13: =GF5&"08" -> 4908 | GK13: =GF5&"09" -> 4909 | GL13: =GF5&"52" -> 4952 | GM13: =GF5&"10" -> 4910 | GN13: =GF5&"11" -> 4911 | GO13: =GF5&"12" -> 4912 | GP13: =GF5&"13" -> 4913 | GQ13: =GF5&"14" -> 4914 | GR13: =GF5&"15" -> 4915 | GS13: =GF5&"16" -> 4916 | GT13: =GF5&"21" -> 4921 | GU13: =GF5&"19" -> 4919 | GV13: =GF5&"51" -> 4951 | GW13: =GF5&"23" -> 4923 | GX13: =GX5&"04" -> КОЛ04904 | GY13: =GX5&"05" -> КОЛ04905 | GZ13: =GX5&"06" -> КОЛ04906 | HA13: =GX5&"07" -> КОЛ04907 | HB13: =GX5&"08" -> КОЛ04908 | HC13: =GX5&"09" -> КОЛ04909 | HD13: =GX5&"52" -> КОЛ04952 | HE13: =GX5&"10" -> КОЛ04910 | HF13: =GX5&"11" -> КОЛ04911 | HG13: =GX5&"12" -> КОЛ04912 | HH13: =GX5&"13" -> КОЛ04913 | HI13: =GX5&"14" -> КОЛ04914 | HJ13: =GX5&"15" -> КОЛ04915 | HK13: =GX5&"16" -> КОЛ04916 | HL13: =GX5&"21" -> КОЛ04921 | HM13: =GX5&"19" -> КОЛ04919 | HN13: =GX5&"51" -> КОЛ04951 | HO13: =GX5&"23" -> КОЛ04923 | HP13: =HP5&"04" -> 5104 | HQ13: =HP5&"05" -> 5105 | HR13: =HP5&"06" -> 5106 | HS13: =HP5&"07" -> 5107 | HT13: =HP5&"08" -> 5108 | HU13: =HP5&"09" -> 5109 | HV13: =HP5&"52" -> 5152 | HW13: =HP5&"10" -> 5110 | HX13: =HP5&"11" -> 5111 | HY13: =HP5&"12" -> 5112 | HZ13: =HP5&"13" -> 5113 | IA13: =HP5&"14" -> 5114 | IB13: =HP5&"15" -> 5115 | IC13: =HP5&"16" -> 5116 | ID13: =HP5&"21" -> 5121 | IE13: =HP5&"19" -> 5119 | IF13: =HP5&"51" -> 5151 | IG13: =HP5&"23" -> 5123 | IH13: =IH5&"04" -> КОЛ05104 | II13: =IH5&"05" -> КОЛ05105 | IJ13: =IH5&"06" -> КОЛ05106 | IK13: =IH5&"07" -> КОЛ05107 | IL13: =IH5&"08" -> КОЛ05108 | IM13: =IH5&"09" -> КОЛ05109 | IN13: =IH5&"52" -> КОЛ05152 | IO13: =IH5&"10" -> КОЛ05110 | IP13: =IH5&"11" -> КОЛ05111 | IQ13: =IH5&"12" -> КОЛ05112 | IR13: =IH5&"13" -> КОЛ05113 | IS13: =IH5&"14" -> КОЛ05114 | IT13: =IH5&"15" -> КОЛ05115 | IU13: =IH5&"16" -> КОЛ05116 | IV13: =IH5&"21" -> КОЛ05121 | IW13: =IH5&"19" -> КОЛ05119 | IX13: =IH5&"51" -> КОЛ05151 | IY13: =IH5&"23" -> КОЛ05123 | IZ13: =IZ5&"04" -> 5204 | JA13: =IZ5&"05" -> 5205 | JB13: =IZ5&"06" -> 5206 | JC13: =IZ5&"07" -> 5207 | JD13: =IZ5&"08" -> 5208 | JE13: =IZ5&"09" -> 5209 | JF13: =IZ5&"52" -> 5252 | JG13: =IZ5&"10" -> 5210 | JH13: =IZ5&"11" -> 5211 | JI13: =IZ5&"12" -> 5212 | JJ13: =IZ5&"13" -> 5213 | JK13: =IZ5&"14" -> 5214 | JL13: =IZ5&"15" -> 5215 | JM13: =IZ5&"16" -> 5216 | JN13: =IZ5&"21" -> 5221 | JO13: =IZ5&"19" -> 5219 | JP13: =IZ5&"51" -> 5251 | JQ13: =IZ5&"23" -> 5223 | JR13: =JR5&"04" -> КОЛ05204 | JS13: =JR5&"05" -> КОЛ05205 | JT13: =JR5&"06" -> КОЛ05206 | JU13: =JR5&"07" -> КОЛ05207 | JV13: =JR5&"08" -> КОЛ05208 | JW13: =JR5&"09" -> КОЛ05209 | JX13: =JR5&"52" -> КОЛ05252 | JY13: =JR5&"10" -> КОЛ05210 | JZ13: =JR5&"11" -> КОЛ05211 | KA13: =JR5&"12" -> КОЛ05212 | KB13: =JR5&"13" -> КОЛ05213 | KC13: =JR5&"14" -> КОЛ05214 | KD13: =JR5&"15" -> КОЛ05215 | KE13: =JR5&"16" -> КОЛ05216 | KF13: =JR5&"21" -> КОЛ05221 | KG13: =JR5&"19" -> КОЛ05219 | KH13: =JR5&"51" -> КОЛ05251 | KI13: =JR5&"23" -> КОЛ05223 | KJ13: =KJ5&"04" -> 5304 | KK13: =KJ5&"05" -> 5305 | KL13: =KJ5&"06" -> 5306 | KM13: =KJ5&"07" -> 5307 | KN13: =KJ5&"08" -> 5308 | KO13: =KJ5&"09" -> 5309 | KP13: =KJ5&"52" -> 5352 | KQ13: =KJ5&"10" -> 5310 | KR13: =KJ5&"11" -> 5311 | KS13: =KJ5&"12" -> 5312 | KT13: =KJ5&"13" -> 5313 | KU13: =KJ5&"14" -> 5314 | KV13: =KJ5&"15" -> 5315 | KW13: =KJ5&"16" -> 5316 | KX13: =KJ5&"21" -> 5321 | KY13: =KJ5&"19" -> 5319 | KZ13: =KJ5&"51" -> 5351 | LA13: =KJ5&"23" -> 5323 | LB13: =LB5&"04" -> КОЛ05304 | LC13: =LB5&"05" -> КОЛ05305 | LD13: =LB5&"06" -> КОЛ05306 | LE13: =LB5&"07" -> КОЛ05307 | LF13: =LB5&"08" -> КОЛ05308 | LG13: =LB5&"09" -> КОЛ05309 | LH13: =LB5&"52" -> КОЛ05352 | LI13: =LB5&"10" -> КОЛ05310 | LJ13: =LB5&"11" -> КОЛ05311 | LK13: =LB5&"12" -> КОЛ05312 | LL13: =LB5&"13" -> КОЛ05313 | LM13: =LB5&"14" -> КОЛ05314 | LN13: =LB5&"15" -> КОЛ05315 | LO13: =LB5&"16" -> КОЛ05316 | LP13: =LB5&"21" -> КОЛ05321 | LQ13: =LB5&"19" -> КОЛ05319 | LR13: =LB5&"51" -> КОЛ05351 | LS13: =LB5&"23" -> КОЛ05323 | LT13: =LT5&"04" -> 5404 | LU13: =LT5&"05" -> 5405 | LV13: =LT5&"06" -> 5406 | LW13: =LT5&"07" -> 5407 | LX13: =LT5&"08" -> 5408 | LY13: =LT5&"09" -> 5409 | LZ13: =LT5&"52" -> 5452 | MA13: =LT5&"10" -> 5410 | MB13: =LT5&"11" -> 5411 | MC13: =LT5&"12" -> 5412 | MD13: =LT5&"13" -> 5413 | ME13: =LT5&"14" -> 5414 | MF13: =LT5&"15" -> 5415 | MG13: =LT5&"16" -> 5416 | MH13: =LT5&"21" -> 5421 | MI13: =LT5&"19" -> 5419 | MJ13: =LT5&"51" -> 5451 | MK13: =LT5&"23" -> 5423 | ML13: =ML5&"04" -> КОЛ05404 | MM13: =ML5&"05" -> КОЛ05405 | MN13: =ML5&"06" -> КОЛ05406 | MO13: =ML5&"07" -> КОЛ05407 | MP13: =ML5&"08" -> КОЛ05408 | MQ13: =ML5&"09" -> КОЛ05409 | MR13: =ML5&"52" -> КОЛ05452 | MS13: =ML5&"10" -> КОЛ05410 | MT13: =ML5&"11" -> КОЛ05411 | MU13: =ML5&"12" -> КОЛ05412 | MV13: =ML5&"13" -> КОЛ05413 | MW13: =ML5&"14" -> КОЛ05414 | MX13: =ML5&"15" -> КОЛ05415 | MY13: =ML5&"16" -> КОЛ05416 | MZ13: =ML5&"21" -> КОЛ05421 | NA13: =ML5&"19" -> КОЛ05419 | NB13: =ML5&"51" -> КОЛ05451 | NC13: =ML5&"23" -> КОЛ05423 | ND13: =ND5&"04" -> 5504 | NE13: =ND5&"05" -> 5505 | NF13: =ND5&"06" -> 5506 | NG13: =ND5&"07" -> 5507 | NH13: =ND5&"08" -> 5508 | NI13: =ND5&"09" -> 5509 | NJ13: =ND5&"52" -> 5552 | NK13: =ND5&"10" -> 5510 | NL13: =ND5&"11" -> 5511 | NM13: =ND5&"12" -> 5512 | NN13: =ND5&"13" -> 5513 | NO13: =ND5&"14" -> 5514 | NP13: =ND5&"15" -> 5515 | NQ13: =ND5&"16" -> 5516 | NR13: =ND5&"21" -> 5521 | NS13: =ND5&"19" -> 5519 | NT13: =ND5&"51" -> 5551 | NU13: =ND5&"23" -> 5523 | NV13: =NV5&"04" -> КОЛ05504 | NW13: =NV5&"05" -> КОЛ05505 | NX13: =NV5&"06" -> КОЛ05506 | NY13: =NV5&"07" -> КОЛ05507 | NZ13: =NV5&"08" -> КОЛ05508 | OA13: =NV5&"09" -> КОЛ05509 | OB13: =NV5&"52" -> КОЛ05552 | OC13: =NV5&"10" -> КОЛ05510 | OD13: =NV5&"11" -> КОЛ05511 | OE13: =NV5&"12" -> КОЛ05512 | OF13: =NV5&"13" -> КОЛ05513 | OG13: =NV5&"14" -> КОЛ05514 | OH13: =NV5&"15" -> КОЛ05515 | OI13: =NV5&"16" -> КОЛ05516 | OJ13: =NV5&"21" -> КОЛ05521 | OK13: =NV5&"19" -> КОЛ05519 | OL13: =NV5&"51" -> КОЛ05551 | OM13: =NV5&"23" -> КОЛ05523 | ON13: =ON5&"04" -> 6004 | OO13: =ON5&"05" -> 6005 | OP13: =ON5&"06" -> 6006 | OQ13: =ON5&"07" -> 6007 | OR13: =ON5&"08" -> 6008 | OS13: =ON5&"09" -> 6009 | OT13: =ON5&"52" -> 6052 | OU13: =ON5&"10" -> 6010 | OV13: =ON5&"11" -> 6011 | OW13: =ON5&"12" -> 6012 | OX13: =ON5&"13" -> 6013 | OY13: =ON5&"14" -> 6014 | OZ13: =ON5&"15" -> 6015 | PA13: =ON5&"16" -> 6016 | PB13: =ON5&"21" -> 6021 | PC13: =ON5&"19" -> 6019 | PD13: =ON5&"51" -> 6051 | PE13: =ON5&"23" -> 6023 | PF13: =PF5&"04" -> КОЛ06004 | PG13: =PF5&"05" -> КОЛ06005 | PH13: =PF5&"06" -> КОЛ06006 | PI13: =PF5&"07" -> КОЛ06007 | PJ13: =PF5&"08" -> КОЛ06008 | PK13: =PF5&"09" -> КОЛ06009 | PL13: =PF5&"52" -> КОЛ06052 | PM13: =PF5&"10" -> КОЛ06010 | PN13: =PF5&"11" -> КОЛ06011 | PO13: =PF5&"12" -> КОЛ06012 | PP13: =PF5&"13" -> КОЛ06013 | PQ13: =PF5&"14" -> КОЛ06014 | PR13: =PF5&"15" -> КОЛ06015 | PS13: =PF5&"16" -> КОЛ06016 | PT13: =PF5&"21" -> КОЛ06021 | PU13: =PF5&"19" -> КОЛ06019 | PV13: =PF5&"51" -> КОЛ06051 | PW13: =PF5&"23" -> КОЛ06023 | PX13: =PX5&"04" -> 5704 | PY13: =PX5&"05" -> 5705 | PZ13: =PX5&"06" -> 5706 | QA13: =PX5&"07" -> 5707 | QB13: =PX5&"08" -> 5708 | QC13: =PX5&"09" -> 5709 | QD13: =PX5&"52" -> 5752 | QE13: =PX5&"10" -> 5710 | QF13: =PX5&"11" -> 5711 | QG13: =PX5&"12" -> 5712 | QH13: =PX5&"13" -> 5713 | QI13: =PX5&"14" -> 5714 | QJ13: =PX5&"15" -> 5715 | QK13: =PX5&"16" -> 5716 | QL13: =PX5&"21" -> 5721 | QM13: =PX5&"19" -> 5719 | QN13: =PX5&"51" -> 5751 | QO13: =PX5&"23" -> 5723
A14: 037 | B14: 01 | C14: РОССИЙСКАЯ ФЕДЕРАЦИЯ
A15: 037 | B15: 01 | C15: резерв
A16: 030 | B16: 02 | C16: ЦЕНТРАЛЬНЫЙ Ф.О.
A17: 14000000000 | B17: 03 | C17: Белгородская область | F17: 7318880500 | I17: 5190341685 | J17: 4930824600 | K17: 259517085 | L17: 4930824600 | O17: 5190341685 | P17: 4930824600 | R17: 259517085 | S17: 5 | V17: 4930824600 | X17: 4930824600 | Y17: 4930824600 | AS17: 200986843 | AT17: 190937500 | AU17: 10049343 | AV17: 190937500 | AY17: 2.0098684e+08 | AZ17: 190937500 | BB17: 10049342 | BC17: 5 | BF17: 190937500 | BH17: 190937500 | BI17: 190937500 | CC17: 27482843 | CD17: 26108700 | CE17: 1374143 | CF17: 26108700 | CI17: 27482843 | CJ17: 26108700 | CL17: 1374143 | CM17: 5 | CP17: 26108700 | CR17: 26108700 | CS17: 26108700 | CU17: 1909311895 | CV17: 1813846300 | CW17: 95465595 | CX17: 1813846300 | DA17: 1.9093119e+09 | DB17: 1813846300 | DD17: 95465594 | DE17: 5 | DH17: 1813846300 | DJ17: 1813846300 | DK17: 1813846300 | EE17: 173284212 | EF17: 164620000 | EG17: 8664212 | EH17: 164620000 | EK17: 173284212 | EL17: 164620000 | EN17: 8664212 | EO17: 5 | ER17: 164620000 | ET17: 164620000 | EU17: 164620000 | FO17: 170357339 | FP17: 130340400 | FQ17: 40016939 | FR17: 130340400 | FU17: 170357339 | FV17: 130340400 | FX17: 40016939 | FY17: 23.49 | GB17: 130340400 | GD17: 130340400 | GE17: 130340400 | GG17: 66205700 | GH17: 36799700 | GI17: 29406000 | GJ17: 36799700 | GM17: 66205700 | GN17: 36799700 | GP17: 29406000 | GQ17: 44.41612 | GT17: 36799700 | GV17: 36799700 | GW17: 36799700 | HQ17: 46070000 | HR17: 21070000 | HS17: 25000000 | HT17: 21070000 | HW17: 46070000 | HX17: 21070000 | HZ17: 25000000 | IA17: 54.26525 | ID17: 21070000 | IF17: 21070000 | IG17: 21070000 | KK17: 6766000 | KL17: 2360000 | KM17: 4406000 | KN17: 2360000 | KQ17: 6766000 | KR17: 2360000 | KT17: 4406000 | KU17: 65.11972 | KX17: 2360000 | KZ17: 2360000 | LA17: 2360000 | OO17: 4000000 | OP17: 1973300 | OQ17: 2026700 | OR17: 1973300 | OU17: 4000000 | OV17: 1973300 | OX17: 2026700 | OY17: 50.6675 | PB17: 1973300 | PD17: 1973300 | PE17: 1973300
A18: 15000000000 | B18: 04 | C18: Брянская область | F18: 10279403600 | I18: 7.9229403e+09 | J18: 7857815100 | K18: 65125222 | L18: 7857815100 | O18: 7.9229403e+09 | P18: 7857815100 | R18: 65125222 | S18: 0.82198 | V18: 7857815100 | X18: 7857815100 | Y18: 7857815100 | AS18: 122544843 | AT18: 116417600 | AU18: 6127243 | AV18: 116417600 | AY18: 122544843 | AZ18: 116417600 | BB18: 6127243 | BC18: 5 | BF18: 116417600 | BH18: 116417600 | BI18: 116417600 | CC18: 270899053 | CD18: 257354100 | CE18: 13544953 | CF18: 257354100 | CI18: 270899053 | CJ18: 257354100 | CL18: 13544953 | CM18: 5 | CP18: 257354100 | CR18: 257354100 | CS18: 257354100 | CU18: 1885358106 | CV18: 1791090200 | CW18: 94267906 | CX18: 1791090200 | DA18: 1885358106 | DB18: 1791090200 | DD18: 94267906 | DE18: 5 | DH18: 1791090200 | DJ18: 1791090200 | DK18: 1791090200 | EE18: 106357900 | EF18: 101040000 | EG18: 5317900 | EH18: 1.0103994e+08 | EK18: 1.0635783e+08 | EL18: 1.0103994e+08 | EN18: 5317891.7 | EO18: 5 | ER18: 1.0103994e+08 | ET18: 101040000 | EU18: 101040000 | FO18: 102785500 | FP18: 85955500 | FQ18: 16830000 | FR18: 85955500 | FU18: 102785500 | FV18: 85955500 | FX18: 16830000 | FY18: 16.3739 | GB18: 85955500 | GD18: 85955500 | GE18: 85955500 | GG18: 26447000 | GH18: 18512900 | GI18: 7934100 | GJ18: 18512900 | GM18: 26447000 | GN18: 18512900 | GP18: 7934100 | GQ18: 30 | GT18: 18512900 | GV18: 18512900 | GW18: 18512900 | HC18: 927823.22 | HJ18: 927823.22 | HQ18: 79389950 | HR18: 43987000 | HS18: 35402950 | HT18: 43972534 | HW18: 79364486 | HX18: 43972534 | HZ18: 35391952 | IA18: 44.59419 | ID18: 43972534 | IF18: 43987000 | IG18: 43987000 | NE18: 8656714 | NF18: 6059700 | NG18: 2597014 | NH18: 6059700 | NK18: 8656714 | NL18: 6059700 | NN18: 2597014 | NO18: 30 | NR18: 6059700 | NT18: 6059700 | NU18: 6059700 | OO18: 1673571 | OP18: 1171500 | OQ18: 502071 | OR18: 1171500 | OU18: 1673571 | OV18: 1171500 | OX18: 502071 | OY18: 29.99998 | PB18: 1171500 | PD18: 1171500 | PE18: 1171500 | QC18: 8243741 | QJ18: 8243741
A19: 17000000000 | B19: 05 | C19: Владимирская область | F19: 1078652500 | I19: 552150600 | J19: 430677400 | K19: 121473200 | L19: 430677400 | M19: 708769 | O19: 552150600 | P19: 430677400 | R19: 121473200 | S19: 22.00001 | T19: 708769 | V19: 430677400 | X19: 430677400 | Y19: 430677400 | AS19: 255433200 | AT19: 242661500 | AU19: 12771700 | AV19: 242661500 | AY19: 255433200 | AZ19: 242661500 | BB19: 12771700 | BC19: 5.00002 | BF19: 242661500 | BH19: 242661500 | BI19: 242661500 | CC19: 78794900 | CD19: 74855100 | CE19: 3939800 | CF19: 74855100 | CI19: 78794900 | CJ19: 74855100 | CL19: 3939800 | CM19: 5.00007 | CP19: 74855100 | CR19: 74855100 | CS19: 74855100 | CU19: 282487800 | CV19: 268363400 | CW19: 14124400 | CX19: 268363400 | CY19: 1511800 | DA19: 282487800 | DB19: 268363400 | DD19: 14124400 | DE19: 5 | DF19: 1511800 | DH19: 268363400 | DJ19: 268363400 | DK19: 268363400 | EE19: 5432500 | EF19: 4346000 | EG19: 1086500 | EH19: 4346000 | EK19: 5432500 | EL19: 4346000 | EN19: 1086500 | EO19: 20 | ER19: 4346000 | ET19: 4346000 | EU19: 4346000 | FO19: 9192000 | FP19: 7191800 | FQ19: 2000200 | FR19: 7191800 | FU19: 9192000 | FV19: 7191800 | FX19: 2000200 | FY19: 21.76023 | GB19: 7191800 | GD19: 7191800 | GE19: 7191800 | GG19: 50310800 | GH19: 17193800 | GI19: 33117000 | GJ19: 17193799 | GM19: 50310796 | GN19: 17193799 | GP19: 33116997 | GQ19: 65.82483 | GT19: 17193799 | GV19: 17193800 | GW19: 17193800 | HQ19: 52482000 | HR19: 31139000 | HS19: 21343000 | HT19: 28081462 | HW19: 47778000 | HX19: 28081462 | HZ19: 19696538 | IA19: 41.22512 | ID19: 28081462 | IF19: 31139000 | IG19: 31139000 | KK19: 11777000 | KL19: 1777000 | KM19: 10000000 | KN19: 1777000 | KQ19: 11777000 | KR19: 1777000 | KT19: 10000000 | KU19: 84.91127 | KX19: 1777000 | KZ19: 1777000 | LA19: 1777000 | OO19: 1077500 | OP19: 447500 | OQ19: 630000 | OR19: 447500 | OU19: 1077500 | OV19: 447500 | OX19: 630000 | OY19: 58.46868 | PB19: 447500 | PD19: 447500 | PE19: 447500
A20: 20000000000 | B20: 06 | C20: Воронежская область | F20: 7211745900 | I20: 3951729100 | J20: 3052540000 | K20: 899189100 | L20: 3.0521208e+09 | O20: 3951169868 | P20: 3.0521208e+09 | R20: 8.9904903e+08 | S20: 22.754 | V20: 3.0521208e+09 | X20: 3052540000 | Y20: 3052540000 | AA20: 1083749300 | AB20: 837153000 | AC20: 246596300 | AD20: 837153000 | AM20: 837153000 | AP20: 837153000 | AQ20: 837153000 | AS20: 339756100 | AT20: 265009100 | AU20: 74747000 | AV20: 2.6476026e+08 | AY20: 3.3943615e+08 | AZ20: 2.647602e+08 | BB20: 74675954 | BC20: 22 | BE20: 63.34 | BF20: 2.647602e+08 | BH20: 265009100 | BI20: 265009100 | CC20: 56707200 | CD20: 53833200 | CE20: 2874000 | CF20: 23153762 | CI20: 23304676 | CJ20: 22123562 | CL20: 1181113.6 | CM20: 5.06814 | CO20: 1030199.6 | CP20: 22123562 | CR20: 53833200 | CS20: 53833200 | CU20: 1836193160 | CV20: 1652145400 | CW20: 184047760 | CX20: 1.6471106e+09 | DA20: 1.8306032e+09 | DB20: 1.6471106e+09 | DD20: 1.834926e+08 | DE20: 10.02361 | DH20: 1.6471106e+09 | DJ20: 1652145400 | DK20: 1652145400 | EE20: 1194992600 | EF20: 1134764600 | EG20: 60228000 | EH20: 1.1347644e+09 | EK20: 1.194992e+09 | EL20: 1.1347644e+09 | EN20: 60227599 | EO20: 5.04 | ER20: 1.1347644e+09 | ET20: 1134764600 | EU20: 1134764600 | FO20: 155201800 | FP20: 105201800 | FQ20: 50000000 | FR20: 1.0466249e+08 | FU20: 1.5440617e+08 | FV20: 1.0466249e+08 | FX20: 49743679 | FY20: 32.21612 | GB20: 1.0466249e+08 | GD20: 105201800 | GE20: 105201800 | GG20: 115435600 | GH20: 69249800 | GI20: 46185800 | GJ20: 69249800 | GM20: 1.1543557e+08 | GN20: 69249800 | GP20: 46185773 | GQ20: 40.01 | GT20: 69249800 | GV20: 69249800 | GW20: 69249800 | HQ20: 70305200 | HR20: 29983000 | HS20: 40322200 | HT20: 29975723 | HW20: 70294213 | HX20: 29975723 | HZ20: 40318490 | IA20: 57.35677 | ID20: 29975723 | IF20: 29983000 | IG20: 29983000 | JA20: 11565100 | JB20: 7655000 | JC20: 3910100 | JD20: 7654999.9 | JG20: 11565100 | JH20: 7654999.9 | JJ20: 3910100 | JK20: 33.80948 | JM20: 0 | JN20: 7654999.9 | JP20: 7655000 | JQ20: 7655000 | KK20: 7648600 | KL20: 3980000 | KM20: 3668600 | KN20: 3968989.5 | KQ20: 7626805.3 | KR20: 3968989.5 | KT20: 3657815.8 | KU20: 47.96 | KX20: 3968989.5 | KZ20: 3980000 | LA20: 3980000 | LU20: 4343600 | LV20: 231000 | LW20: 4112600 | LX20: 231000 | MA20: 4343501 | MB20: 230994.73 | MD20: 4112506.3 | ME20: 94.68183 | MG20: 5.27 | MH20: 230994.73 | MJ20: 231000 | MK20: 231000 | QC20: 92595689 | QJ20: 92595689
A21: 24000000000 | B21: 07 | C21: Ивановская область | F21: 361559300 | I21: 44914570 | J21: 38497000 | K21: 6417570.3 | L21: 38497000 | O21: 44914570 | P21: 38497000 | R21: 6417570.3 | S21: 14.28839 | V21: 38497000 | X21: 38497000 | Y21: 38497000 | AS21: 97230000 | AT21: 92368500 | AU21: 4861500 | AV21: 92368500 | AY21: 97230000 | AZ21: 92368500 | BB21: 4861500 | BC21: 5 | BF21: 92368500 | BH21: 92368500 | BI21: 92368500 | CC21: 60757053 | CD21: 57719200 | CE21: 3037852.6 | CF21: 57719200 | CG21: 669273 | CI21: 60757053 | CJ21: 57719200 | CL21: 3037852.6 | CM21: 5 | CN21: 669273 | CP21: 57719200 | CR21: 57719200 | CS21: 57719200 | CU21: 1.1113045e+08 | CV21: 105572300 | CW21: 5558145.3 | CX21: 1.0557165e+08 | DA21: 1.1112979e+08 | DB21: 1.0557165e+08 | DD21: 5558145.3 | DE21: 5.00149 | DH21: 1.0557165e+08 | DJ21: 105572300 | DK21: 105572300 | EE21: 50726851 | EF21: 48188900 | EG21: 2537951 | EH21: 48188900 | EK21: 50726851 | EL21: 48188900 | EN21: 2537951 | EO21: 5.00317 | ER21: 48188900 | ET21: 48188900 | EU21: 48188900 | FO21: 2019975.3 | FP21: 1800000 | FQ21: 219975.31 | FR21: 1800000 | FU21: 2019975.3 | FV21: 1800000 | FX21: 219975.31 | FY21: 10.89 | GB21: 1800000 | GD21: 1800000 | GE21: 1800000 | GG21: 11125400 | GH21: 5125400 | GI21: 6000000 | GJ21: 5099310.5 | GM21: 11068614 | GN21: 5099310.5 | GP21: 5969303.5 | GQ21: 53.93 | GT21: 5099310.5 | GV21: 5125400 | GW21: 5125400 | HQ21: 26388000 | HR21: 12288000 | HS21: 14100000 | HT21: 8074352.7 | HW21: 17339357 | HX21: 8074352.7 | HZ21: 9265004.4 | IA21: 53.43338 | ID21: 8074352.7 | IF21: 12288000 | IG21: 12288000 | QC21: 174112.1 | QJ21: 174112.1
A22: 29000000000 | B22: 08 | C22: Калужская область | F22: 2847157700 | I22: 1069419134 | J22: 1014985700 | K22: 54433434 | L22: 1.0149855e+09 | O22: 1.0694189e+09 | P22: 1.0149855e+09 | R22: 54433426 | S22: 5.09 | V22: 1.0149855e+09 | X22: 1014985700 | Y22: 1014985700 | AA22: 136952183 | AB22: 129982400 | AC22: 6969783 | AD22: 129982400 | AG22: 136952183 | AH22: 129982400 | AJ22: 6969783 | AK22: 5.08921 | AN22: 129982400 | AP22: 129982400 | AQ22: 129982400 | AS22: 113914900 | AT22: 101383900 | AU22: 12531000 | AV22: 101383900 | AY22: 113914900 | AZ22: 101383900 | BB22: 12531000 | BC22: 11.00032 | BF22: 101383900 | BH22: 101383900 | BI22: 101383900 | CC22: 79177900 | CD22: 70467900 | CE22: 8710000 | CF22: 70467900 | CI22: 79177900 | CJ22: 70467900 | CL22: 8710000 | CM22: 11.00054 | CP22: 70467900 | CR22: 70467900 | CS22: 70467900 | CU22: 183110889 | CV22: 164799800 | CW22: 18311089 | CX22: 164799800 | DA22: 183110889 | DB22: 164799800 | DD22: 18311089 | DE22: 10 | DH22: 164799800 | DJ22: 164799800 | DK22: 164799800 | EE22: 1380558316 | EF22: 1311530400 | EG22: 69027916 | EH22: 1.3115304e+09 | EK22: 1.3805583e+09 | EL22: 1.3115304e+09 | EN22: 69027916 | EO22: 5 | ER22: 1.3115304e+09 | ET22: 1311530400 | EU22: 1311530400 | GD22: 2000000 | GE22: 0 | GG22: 84345700 | GH22: 44345700 | GI22: 40000000 | GJ22: 44345700 | GM22: 84345700 | GN22: 44345700 | GP22: 40000000 | GQ22: 47.42388 | GS22: 0 | GT22: 44345700 | GV22: 44345700 | GW22: 44345700 | HQ22: 10000000 | HR22: 7000000 | HS22: 3000000 | HT22: 7000000 | HU22: 27839.8 | HW22: 10000000 | HX22: 7000000 | HZ22: 3000000 | IA22: 30 | IB22: 27839.8 | ID22: 7000000 | IF22: 7000000 | IG22: 7000000 | LU22: 6505500 | LV22: 505500 | LW22: 6000000 | LX22: 505500 | MA22: 6505500 | MB22: 505500 | MD22: 6000000 | ME22: 92.22965 | MH22: 505500 | MJ22: 505500 | MK22: 505500 | OO22: 6156400 | OP22: 2156400 | OQ22: 4000000 | OR22: 2156400 | OU22: 6156400 | OV22: 2156400 | OX22: 4000000 | OY22: 64.97304 | PB22: 2156400 | PD22: 2156400 | PE22: 2156400 | QC22: 125900 | QJ22: 125900
A23: 34000000000 | B23: 09 | C23: Костромская область | F23: 239509700 | I23: 35472900 | J23: 25252800 | K23: 10220100 | L23: 25252800 | M23: 1050841.5 | O23: 35472839 | P23: 25252759 | R23: 10220080 | S23: 28.811 | T23: 1050841.5 | U23: 40.96 | V23: 25252759 | X23: 25252800 | Y23: 25252800 | AS23: 53179000 | AT23: 50520000 | AU23: 2659000 | AV23: 50519959 | AY23: 53178957 | AZ23: 50519959 | BB23: 2658997.8 | BC23: 5.00009 | BE23: 0.01 | BF23: 50519959 | BH23: 50520000 | BI23: 50520000 | CC23: 68853900 | CD23: 65410900 | CE23: 3443000 | CF23: 65410900 | CI23: 68853579 | CJ23: 65410595 | CL23: 3442984 | CM23: 5.00044 | CO23: 305 | CP23: 65410595 | CR23: 65410900 | CS23: 65410900 | CU23: 81291230 | CV23: 77226100 | CW23: 4065130 | CX23: 77223494 | DA23: 81288486 | DB23: 77223493 | DD23: 4064992.8 | DE23: 5.0007 | DG23: 0.62 | DH23: 77223493 | DJ23: 77226100 | DK23: 77226100 | EE23: 3891500 | EF23: 3696900 | EG23: 194600 | EH23: 3696900 | EI23: 0 | EK23: 3891500 | EL23: 3696900 | EN23: 194600 | EO23: 5.00064 | EP23: 0 | EQ23: 0.02 | ER23: 3696900 | ET23: 3696900 | EU23: 3696900 | FO23: 3500119.1 | FP23: 2938000 | FQ23: 562119.1 | FR23: 2938000 | FS23: 12502 | FU23: 3500119.1 | FV23: 2938000 | FX23: 562119.1 | FY23: 16.06 | FZ23: 12502 | GB23: 2938000 | GD23: 2938000 | GE23: 2938000 | GG23: 21427500 | GH23: 10911500 | GI23: 10516000 | GJ23: 10911499 | GK23: 151600 | GM23: 21427499 | GN23: 10911499 | GP23: 10516000 | GQ23: 49.07712 | GR23: 151600 | GT23: 10911499 | GV23: 10911500 | GW23: 10911500 | HQ23: 5801000 | HR23: 2800000 | HS23: 3001000 | HT23: 2800000 | HW23: 5801000 | HX23: 2800000 | HZ23: 3001000 | IA23: 51.73246 | ID23: 2800000 | IF23: 2800000 | IG23: 2800000 | KK23: 962000 | KL23: 600000 | KM23: 362000 | KN23: 600000 | KQ23: 962000 | KR23: 600000 | KT23: 362000 | KU23: 37.62994 | KX23: 600000 | KZ23: 600000 | LA23: 600000 | OO23: 666400 | OP23: 153500 | OQ23: 512900 | OR23: 153500 | OU23: 666389.7 | OV23: 153497.63 | OX23: 512892.07 | OY23: 76.96579 | PA23: 2.37 | PB23: 153497.63 | PD23: 153500 | PE23: 153500 | QC23: 8042430.7 | QJ23: 8042430.7
A24: 38000000000 | B24: 10 | C24: Курская область | F24: 5837183000 | I24: 3712012388 | J24: 3223987600 | K24: 488024788 | L24: 3.2239865e+09 | O24: 3711987973 | P24: 3.2239687e+09 | R24: 4.8801932e+08 | S24: 13.14711 | U24: 17845.34 | V24: 3.2239687e+09 | X24: 3223987600 | Y24: 3223987600 | AA24: 1044819228 | AB24: 886286200 | AC24: 158533028 | AD24: 886286200 | AG24: 1.0116328e+09 | AH24: 8.5886954e+08 | AJ24: 1.5276322e+08 | AK24: 15.10066 | AM24: 27416662 | AN24: 8.5886954e+08 | AP24: 886286200 | AQ24: 886286200 | AS24: 79751053 | AT24: 75763500 | AU24: 3987553 | AV24: 75762114 | AY24: 79749594 | AZ24: 75762114 | BB24: 3987480.5 | BC24: 5 | BF24: 75762114 | BH24: 75763500 | BI24: 75763500 | CC24: 11729895 | CD24: 11143400 | CE24: 586495 | CF24: 3308097.5 | CI24: 3482208 | CJ24: 3308097.5 | CL24: 174110.5 | CM24: 5 | CP24: 3308097.5 | CR24: 11143400 | CS24: 11143400 | CU24: 502546843 | CV24: 477419500 | CW24: 25127343 | CX24: 4.7737386e+08 | DA24: 5.0249881e+08 | DB24: 4.7737386e+08 | DD24: 25124945 | DE24: 5 | DH24: 4.7737386e+08 | DJ24: 477419500 | DK24: 477419500 | EE24: 1169890339 | EF24: 1063762400 | EG24: 106127939 | EH24: 1063762400 | EK24: 1169890339 | EL24: 1063762400 | EN24: 106127939 | EO24: 9.07161 | ER24: 1063762400 | ET24: 1063762400 | EU24: 1063762400 | FO24: 32417466 | FP24: 27062100 | FQ24: 5355366 | FR24: 27062100 | FU24: 32417466 | FV24: 27062100 | FX24: 5355366 | FY24: 16.52 | GB24: 27062100 | GD24: 27062100 | GE24: 27062100 | GG24: 57820100 | GH24: 32743100 | GI24: 25077000 | GJ24: 32743100 | GK24: 778220 | GM24: 57361940 | GN24: 32483647 | GP24: 24878293 | GQ24: 43.37073 | GR24: 778220 | GS24: 259452.71 | GT24: 32483647 | GV24: 32743100 | GW24: 32743100 | HC24: 470796.85 | HJ24: 470796.85 | HQ24: 102060265 | HR24: 35746000 | HS24: 66314265 | HT24: 35746000 | HW24: 102060265 | HX24: 35746000 | HZ24: 66314265 | IA24: 64.9756 | ID24: 35746000 | IF24: 35746000 | IG24: 35746000 | KK24: 7110750 | KL24: 841000 | KM24: 6269750 | KN24: 841000 | KQ24: 7110750 | KR24: 841000 | KT24: 6269750 | KU24: 88.17284 | KX24: 841000 | KZ24: 841000 | LA24: 841000 | LU24: 5925500 | LV24: 2086000 | LW24: 3839500 | LX24: 2086000 | MA24: 5925500 | MB24: 2086000 | MD24: 3839500 | ME24: 64.79622 | MH24: 2086000 | MJ24: 2086000 | MK24: 2086000 | OO24: 502700 | OP24: 342200 | OQ24: 160500 | OR24: 342200 | OU24: 502700 | OV24: 342200 | OX24: 160500 | OY24: 31.92759 | PB24: 342200 | PD24: 342200 | PE24: 342200 | QC24: 8075739.6 | QJ24: 8075739.6
A25: 42000000000 | B25: 11 | C25: Липецкая область | F25: 3587856700 | I25: 1.7966285e+09 | J25: 1704146100 | K25: 92482422 | L25: 1.7041461e+09 | O25: 1.7966285e+09 | P25: 1.7041461e+09 | R25: 92482422 | S25: 5.14755 | V25: 1.7041461e+09 | X25: 1704146100 | Y25: 1704146100 | AS25: 92047718 | AT25: 84683900 | AU25: 7363818 | AV25: 84683900 | AY25: 92047717 | AZ25: 84683900 | BB25: 7363817.4 | BC25: 8 | BF25: 84683900 | BH25: 84683900 | BI25: 84683900 | CC25: 9576087 | CD25: 8810000 | CE25: 766087 | CF25: 8809999.4 | CI25: 9576086.4 | CJ25: 8809999.4 | CL25: 766087 | CM25: 8 | CP25: 8809999.4 | CR25: 8810000 | CS25: 8810000 | CU25: 7.5762774e+08 | CV25: 697017500 | CW25: 60610242 | CX25: 6.9701535e+08 | DA25: 7.5762541e+08 | DB25: 6.9701535e+08 | DD25: 60610055 | DE25: 8 | DH25: 6.9701535e+08 | DJ25: 697017500 | DK25: 697017500 | EE25: 983136758 | EF25: 933979800 | EG25: 49156958 | EH25: 933979800 | EK25: 9.8313663e+08 | EL25: 933979800 | EN25: 49156832 | EO25: 5 | ER25: 933979800 | ET25: 933979800 | EU25: 933979800 | GG25: 1.8375628e+08 | GH25: 95755400 | GI25: 88000885 | GJ25: 95755400 | GM25: 1.8375628e+08 | GN25: 95755400 | GP25: 88000885 | GQ25: 47.89 | GT25: 95755400 | GV25: 95755400 | GW25: 95755400 | HQ25: 54310763 | HR25: 23213000 | HS25: 31097763 | HT25: 23212816 | HW25: 54310291 | HX25: 23212816 | HZ25: 31097475 | IA25: 57.2589 | ID25: 23212816 | IF25: 23213000 | IG25: 23213000 | KK25: 39812383 | KL25: 2122000 | KM25: 37690383 | KN25: 2121999.6 | KQ25: 39812382 | KR25: 2121999.6 | KT25: 37690383 | KU25: 94.67 | KX25: 2121999.6 | KZ25: 2122000 | LA25: 2122000 | NE25: 71232674 | NF25: 34227300 | NG25: 37005374 | NH25: 34227300 | NK25: 71232674 | NL25: 34227300 | NN25: 37005374 | NO25: 51.95 | NR25: 34227300 | NT25: 34227300 | NU25: 34227300 | OO25: 11401812 | OP25: 3901700 | OQ25: 7500111.8 | OR25: 3901700 | OU25: 11401812 | OV25: 3901700 | OX25: 7500111.8 | OY25: 65.78 | PB25: 3901700 | PD25: 3901700 | PE25: 3901700 | QC25: 5815871.5 | QJ25: 5815871.5
