Workbook
Name date: data_1!$D$2
Name Print_Area: '1.2'!$A$1:$R$106
Name Print_Area: '1.4 (1.4.1-1.4.2)'!$A$2:$BG$109
Name Print_Area: '1.7'!$A$1:$R$106
Name Print_Area: Итого!$A$1:$S$106
Name Print_Titles: '1'!$B:$B,'1'!$7:$11
Name Print_Titles: '1.1'!$B:$B,'1.1'!$7:$11
Name Print_Titles: '1.2'!$B:$B,'1.2'!$7:$11
Name Print_Titles: '1.3'!$B:$B,'1.3'!$7:$11
Name Print_Titles: '1.4'!$B:$B,'1.4'!$7:$11
Name Print_Titles: '1.4 (1.4.1-1.4.2)'!$B:$C,'1.4 (1.4.1-1.4.2)'!$7:$12
Name Print_Titles: '1.5'!$B:$B,'1.5'!$7:$11
Name Print_Titles: '1.6'!$B:$B,'1.6'!$7:$11
Name Print_Titles: '1.7'!$B:$B,'1.7'!$7:$11
Name Print_Titles: '2'!$B:$B,'2'!$7:$11
Name Print_Titles: '3'!$B:$B,'3'!$7:$11
Name Print_Titles: '4'!$B:$B,'4'!$7:$11
Name Print_Titles: Итого!$C:$C,Итого!$7:$11
Name ЕдиницаВыбор: Списки!$H$17:$H$19
Name ЕдиницаДоведение: #REF!
Name ЕдиницаМатрица: Списки!$H$17:$I$19
Name КОЛ01704: data_1!$CT$14:$CT$108
Name КОЛ01705: data_1!$CU$14:$CU$108
Name КОЛ01706: data_1!$CV$14:$CV$108
Name КОЛ01707: data_1!$CW$14:$CW$108
Name КОЛ01708: data_1!$CX$14:$CX$108
Name КОЛ01709: data_1!$CY$14:$CY$108
Name КОЛ01710: data_1!$DA$14:$DA$108
Name КОЛ01711: data_1!$DB$14:$DB$108
Name КОЛ01712: data_1!$DC$14:$DC$108
Name КОЛ01713: data_1!$DD$14:$DD$108
Name КОЛ01714: data_1!$DE$14:$DE$108
Name КОЛ01715: data_1!$DF$14:$DF$108
Name КОЛ01716: data_1!$DG$14:$DG$108
Name КОЛ01719: data_1!$DI$14:$DI$108
Name КОЛ01721: data_1!$DH$14:$DH$108
Name КОЛ01723: data_1!$DK$14:$DK$108
Name КОЛ01751: data_1!$DJ$14:$DJ$108
Name КОЛ01752: data_1!$CZ$14:$CZ$108
Name КОЛ03704: data_1!$ED$14:$ED$108
Name КОЛ03705: data_1!$EE$14:$EE$108
Name КОЛ03706: data_1!$EF$14:$EF$108
Name КОЛ03707: data_1!$EG$14:$EG$108
Name КОЛ03708: data_1!$EH$14:$EH$108
Name КОЛ03709: data_1!$EI$14:$EI$108
Name КОЛ03710: data_1!$EK$14:$EK$108
Name КОЛ03711: data_1!$EL$14:$EL$108
Name КОЛ03712: data_1!$EM$14:$EM$108
Name КОЛ03713: data_1!$EN$14:$EN$108
Name КОЛ03714: data_1!$EO$14:$EO$108
Name КОЛ03715: data_1!$EP$14:$EP$108
Name КОЛ03716: data_1!$EQ$14:$EQ$108
Name КОЛ03719: data_1!$ES$14:$ES$108
Name КОЛ03721: data_1!$ER$14:$ER$108
Name КОЛ03723: data_1!$EU$14:$EU$108
Name КОЛ03751: data_1!$ET$14:$ET$108
Name КОЛ03752: data_1!$EJ$14:$EJ$108
Name КОЛ04904: data_1!$FN$14:$FN$108
Name КОЛ04905: data_1!$FO$14:$FO$108
Name КОЛ04906: data_1!$FP$14:$FP$108

Sheet data_1
C2: по состояню на | D2: Декабрь 2019 г.
H5: 37 | Z5: 62 | AR5: 45 | BJ5: КОЛ061 | CB5: 17 | CT5: КОЛ017 | DL5: 59 | ED5: КОЛ037 | EV5: 61 | FN5: КОЛ049 | FT5: ё | GF5: 51 | GX5: КОЛ051 | HP5: 52 | IH5: КОЛ052 | IZ5: 53 | JR5: КОЛ053 | KJ5: 54 | LB5: КОЛ054 | LT5: 58 | ML5: КОЛ055 | ND5: 60 | NV5: КОЛ060 | ON5: 57 | PF5: 63 | PX5: КОЛ064 | QP5: 65 | RH5: КОЛ066 | RZ5: 67 | SR5: КОЛ068 | TJ5: 69 | UB5: КОЛ070
H6: 1.1 - Субсидии на оказание несвязанной поддержки сельскохозяйственным товаропроизводителям в области растениеводства, КБК: 04 05 25УВ355410 523 | Z6: 1.2- Субсидии на повышение продуктивности в молочном скотоводстве КБК: 04 05 25УВ355420 521 | AR6: 1.3-Субсидии на содействие достижению целевых показателей региональных программ развития агропромышленного комплекса КБК: 04 05 25УВ355430 523 | BJ6: 1.4-Иные межбюджетные трансферты на возмещение части затрат на уплату процентов по инвестиционным кредитам (займам) в агропромышленном комплексе 04 05 25УВ254330 540 | CB6: 1.5 - Реализация мероприятий в области мелиорации земель сельскохозяйственного назначения КБК: 04 05 25ФВ155680 521 | CT6: 1.5 - Реализация мероприятий в области мелиорации земель сельскохозяйственного назначения (экспорт) КБК: 04 05 25УT255680 521 | DL6: 1.6.1 - Иные межбюджетные трансферты на возмещение части прямых понесенных затрат на создание и (или) модернизацию объектов агропромышленного комплекса КБК 04 05 25УВ254720 500 | ED6: 1.7 - Создание системы поддержки фермеров и развитие сельской кооперации, КБК: 04 05 25УI754800 540 | EV6: 2.1-Субсидии на обеспечение жильем граждан, проживающих и работающих в сельской местности, и на обеспечение жильем молодых семей и молодых специалистов, проживающих и работающих в сельской местности 10 03 25Ф0255670 521 | FN6: 2.1.2 КБК 10 03 0000058000 521 | GF6: 2.2 - "Устойчивое развитие сельских территорий на 2014 - 2017 годы и на период до 2020 года" (ЖКХ), КБК: 05 02 25Ф0255670 522 | GX6: 2.2.1 - Прочее "Устойчивое развитие сельских территорий на 2014 - 2017 годы и на период до 2020 года" (ЖКХ), КБК: 05 02 0000058000 522 | HP6: 2.2.2 - 2018 "Устойчивое развитие сельских территорий на 2014 - 2017 годы и на период до 2020 года" (Образование), КБК: 07 02 022E155670 522 | IH6: 2.2.3 -Прочее "Устойчивое развитие сельских территорий на 2014 - 2017 годы и на период до 2020 года" (Образование):, КБК: 07 02 0000058000 522 | IZ6: 2.2.4 -2018 "Устойчивое развитие сельских территорий на 2014 - 2017 годы и на период до 2020 года" (Медицина), КБК: 09 02 01КN155670 522 | JR6: 2.2.5 - Устойчивое развитие сельских территорий на 2014 - 2017 годы и на период до 2020 года" (Медицина):, КБК: 09 02 0000058000 522 | KJ6: 2.2.6 - 2018 "Устойчивое развитие сельских территорий на 2014 - 2017 годы и на период до 2020 года" (Спорт):, КБК: 11 01 131P555670 522 | LB6: 2.2.7 - Прочее 2018 "Устойчивое развитие сельских территорий на 2014 - 2017 годы и на период до 2020 года" (Спорт):, КБК: 11 01 0000058000 522 | LT6: 2.3 - Субсидии на комплексную компактную застройку, КБК: 04 05 25Ф0255670 522 | ML6: 2.3.1- Субсидии на комплексную компактную застройку, КБК: 04 05 0000058000 522 | ND6: 2.4. - Реализация проектов грантовой поддержки местных инициатив граждан, проживающих в сельской местности, КБК: 04 05 25Ф0255670 521 | NV6: 2.4.1. - Реализация проектов грантовой поддержки местных инициатив граждан, проживающих в сельской местности КБК: 04 05 0000058000 521 | ON6: 3.-Целевые межбюджетные трансферты прошлых лет, полученные из федерального бюджета, КБК: 04 05 0000058000 521 | PF6: 3.1.-Целевые межбюджетные трансферты прошлых лет, полученные из федерального бюджета 04 05 0000058000 540 | PX6: 1.6.2 - Иные межбюджетные трансферты на возмещение части прямых понесенных затрат на создание и (или) модернизацию объектов агропромышленного комплекса за счет средств резервного фонда Правительства Российской Федерации, КБК 04 05 25УВ25472F 540 | QP6: 2.2.2 - Строительство и реконструкция объектов социальной и инженерной инфраструктуры, расположенных в сельской местности (ЖКХ, резерв), КБК 05 02 25Ф025567F 521 | RH6: 3.2 - Целевые межбюджетные трансферты прошлых лет, полученные из федерального бюджета, КБК 04 05 0000058000 523 | RZ6: 4.1 - Иные межбюджетные трансферты на осуществление компенсации сельскохозяйственным товаропроизводителям ущерба, причиненного в результате чрезвычайных ситуаций, КБК 04 05 25Ф0353700 540 | SR6: 4.2 - Иные межбюджетные трансферты на осуществление компенсации сельскохозяйственным товаропроизводителям ущерба, причиненного в результате чрезвычайных ситуаций, КБК 04 05 25Ф0356430 540 | TJ6: 4.3 - Иные межбюджетные трансферты на осуществление компенсации сельскохозяйственным товаропроизводителям ущерба, причиненного в результате чрезвычайных ситуаций, КБК 04 05 25Ф035473F 540 | UB6: 4.4 - Иные межбюджетные трансферты на осуществление компенсации сельскохозяйственным товаропроизводителям ущерба, причиненного в результате чрезвычайных ситуаций, КБК 04 05 25Ф0353710 540
F7: Предельный объем финансирования на текущую дату | G7: Остаток предельных объемов финансирования | H7: Остаток средств федерального бюджета на 01.01.2019 г., потребность в котором подтверждена | I7: Предусмотрено ср-в на т.г всего | J7: федерального бюджета | K7: бюджета субъекта Российской Федерации | L7: Получено из федерального бюджета в текущем году на отчетную дату | M7: Восстановлено средств федерального бюджета с начала т.г. по различным основаниям | N7: Подтверждение восстановления | O7: Пречислено на отчетную дату всего | P7: федерального бюджета | Q7: в т.с. За счет остатка | R7: бюджета субъекта Российской Федерации | S7: Фактический уровень финансирования | T7: Возвращено в федеральный бюджет в текущем году на отчетную дату | U7: Остаток средств ф.б на лиц. Счетах | V7: Кассовые расходы на текущую дату | W7: Прогноз остатков средств федерального бюджета на 31 декабря т.г. | X7: Лимит по распоряжению | Y7: Доведено РБС | Z7: Остаток средств федерального бюджета на 01.01.2019 г., потребность в котором подтверждена | AA7: Предусмотрено ср-в на т.г всего | AB7: федерального бюджета | AC7: бюджета субъекта Российской Федерации | AD7: Получено из федерального бюджета в текущем году на отчетную дату | AE7: Восстановлено средств федерального бюджета с начала т.г. по различным основаниям | AF7: Подтверждение восстановления | AG7: Пречислено на отчетную дату всего | AH7: федерального бюджета | AI7: в т.с. За счет остатка | AJ7: бюджета субъекта Российской Федерации | AK7: Фактический уровень финансирования | AL7: Возвращено в федеральный бюджет в текущем году на отчетную дату | AM7: Остаток средств ф.б на лиц. Счетах | AN7: Кассовые расходы на текущую дату | AO7: Прогноз остатков средств федерального бюджета на 31 декабря т.г. | AP7: Лимит по распоряжению | AQ7: Доведено РБС | AR7: Остаток средств федерального бюджета на 01.01.2019 г., потребность в котором подтверждена | AS7: Предусмотрено ср-в на т.г всего | AT7: федерального бюджета | AU7: бюджета субъекта Российской Федерации | AV7: Получено из федерального бюджета в текущем году на отчетную дату | AW7: Восстановлено средств федерального бюджета с начала т.г. по различным основаниям | AX7: Подтверждение восстановления | AY7: Пречислено на отчетную дату всего | AZ7: федерального бюджета | BA7: в т.с. За счет остатка | BB7: бюджета субъекта Российской Федерации | BC7: Фактический уровень финансирования | BD7: Возвращено в федеральный бюджет в текущем году на отчетную дату | BE7: Остаток средств ф.б на лиц. Счетах | BF7: Кассовые расходы на текущую дату | BG7: Прогноз остатков средств федерального бюджета на 31 декабря т.г. | BH7: Лимит по распоряжению | BI7: Доведено РБС | BJ7: Остаток средств федерального бюджета на 01.01.2019 г., потребность в котором подтверждена | BK7: Предусмотрено ср-в на т.г всего | BL7: федерального бюджета | BM7: бюджета субъекта Российской Федерации | BN7: Получено из федерального бюджета в текущем году на отчетную дату | BO7: Восстановлено средств федерального бюджета с начала т.г. по различным основаниям | BP7: Подтверждение восстановления | BQ7: Пречислено на отчетную дату всего | BR7: федерального бюджета | BS7: в т.с. За счет остатка | BT7: бюджета субъекта Российской Федерации | BU7: Фактический уровень финансирования | BV7: Возвращено в федеральный бюджет в текущем году на отчетную дату | BW7: Остаток средств ф.б на лиц. Счетах | BX7: Кассовые расходы на текущую дату | BY7: Прогноз остатков средств федерального бюджета на 31 декабря т.г. | BZ7: Лимит по распоряжению | CA7: Доведено РБС | CB7: Остаток средств федерального бюджета на 01.01.2019 г., потребность в котором подтверждена | CC7: Предусмотрено ср-в на т.г всего | CD7: федерального бюджета | CE7: бюджета субъекта Российской Федерации | CF7: Получено из федерального бюджета в текущем году на отчетную дату | CG7: Восстановлено средств федерального бюджета с начала т.г. по различным основаниям | CH7: Подтверждение восстановления | CI7: Пречислено на отчетную дату всего | CJ7: федерального бюджета | CK7: в т.с. За счет остатка | CL7: бюджета субъекта Российской Федерации | CM7: Фактический уровень финансирования | CN7: Возвращено в федеральный бюджет в текущем году на отчетную дату | CO7: Остаток средств ф.б на лиц. Счетах | CP7: Кассовые расходы на текущую дату | CQ7: Прогноз остатков средств федерального бюджета на 31 декабря т.г. | CR7: Лимит по распоряжению | CS7: Доведено РБС | CT7: Остаток средств федерального бюджета на 01.01.2019 г., потребность в котором подтверждена | CU7: Предусмотрено ср-в на т.г всего | CV7: федерального бюджета | CW7: бюджета субъекта Российской Федерации | CX7: Получено из федерального бюджета в текущем году на отчетную дату | CY7: Восстановлено средств федерального бюджета с начала т.г. по различным основаниям | CZ7: Подтверждение восстановления | DA7: Пречислено на отчетную дату всего | DB7: федерального бюджета | DC7: в т.с. За счет остатка | DD7: бюджета субъекта Российской Федерации | DE7: Фактический уровень финансирования | DF7: Возвращено в федеральный бюджет в текущем году на отчетную дату | DG7: Остаток средств ф.б на лиц. Счетах | DH7: Кассовые расходы на текущую дату | DI7: Прогноз остатков средств федерального бюджета на 31 декабря т.г. | DJ7: Лимит по распоряжению | DK7: Доведено РБС | DL7: Остаток средств федерального бюджета на 01.01.2019 г., потребность в котором подтверждена | DM7: Предусмотрено ср-в на т.г всего | DN7: федерального бюджета | DO7: бюджета субъекта Российской Федерации | DP7: Получено из федерального бюджета в текущем году на отчетную дату | DQ7: Восстановлено средств федерального бюджета с начала т.г. по различным основаниям | DR7: Подтверждение восстановления | DS7: Пречислено на отчетную дату всего | DT7: федерального бюджета | DU7: в т.с. За счет остатка | DV7: бюджета субъекта Российской Федерации | DW7: Фактический уровень финансирования | DX7: Возвращено в федеральный бюджет в текущем году на отчетную дату | DY7: Остаток средств ф.б на лиц. Счетах | DZ7: Кассовые расходы на текущую дату | EA7: Прогноз остатков средств федерального бюджета на 31 декабря т.г. | EB7: Лимит по распоряжению | EC7: Доведено РБС | ED7: Остаток средств федерального бюджета на 01.01.2019 г., потребность в котором подтверждена | EE7: Предусмотрено ср-в на т.г всего | EF7: федерального бюджета | EG7: бюджета субъекта Российской Федерации | EH7: Получено из федерального бюджета в текущем году на отчетную дату | EI7: Восстановлено средств федерального бюджета с начала т.г. по различным основаниям | EJ7: Подтверждение восстановления | EK7: Пречислено на отчетную дату всего | EL7: федерального бюджета | EM7: в т.с. За счет остатка | EN7: бюджета субъекта Российской Федерации | EO7: Фактический уровень финансирования | EP7: Возвращено в федеральный бюджет в текущем году на отчетную дату | EQ7: Остаток средств ф.б на лиц. Счетах | ER7: Кассовые расходы на текущую дату | ES7: Прогноз остатков средств федерального бюджета на 31 декабря т.г. | ET7: Лимит по распоряжению | EU7: Доведено РБС | EV7: Остаток средств федерального бюджета на 01.01.2019 г., потребность в котором подтверждена | EW7: Предусмотрено ср-в на т.г всего | EX7: федерального бюджета | EY7: бюджета субъекта Российской Федерации | EZ7: Получено из федерального бюджета в текущем году на отчетную дату | FA7: Восстановлено средств федерального бюджета с начала т.г. по различным основаниям | FB7: Подтверждение восстановления | FC7: Пречислено на отчетную дату всего | FD7: федерального бюджета | FE7: в т.с. За счет остатка | FF7: бюджета субъекта Российской Федерации | FG7: Фактический уровень финансирования | FH7: Возвращено в федеральный бюджет в текущем году на отчетную дату | FI7: Остаток средств ф.б на лиц. Счетах | FJ7: Кассовые расходы на текущую дату | FK7: Прогноз остатков средств федерального бюджета на 31 декабря т.г. | FL7: Лимит по распоряжению | FM7: Доведено РБС | FN7: Остаток средств федерального бюджета на 01.01.2019 г., потребность в котором подтверждена | FO7: Предусмотрено ср-в на т.г всего | FP7: федерального бюджета | FQ7: бюджета субъекта Российской Федерации | FR7: Получено из федерального бюджета в текущем году на отчетную дату | FS7: Восстановлено средств федерального бюджета с начала т.г. по различным основаниям | FT7: Подтверждение восстановления | FU7: Пречислено на отчетную дату всего | FV7: федерального бюджета | FW7: в т.с. За счет остатка | FX7: бюджета субъекта Российской Федерации | FY7: Фактический уровень финансирования | FZ7: Возвращено в федеральный бюджет в текущем году на отчетную дату | GA7: Остаток средств ф.б на лиц. Счетах | GB7: Кассовые расходы на текущую дату | GC7: Прогноз остатков средств федерального бюджета на 31 декабря т.г. | GD7: Лимит по распоряжению | GE7: Доведено РБС | GF7: Остаток средств федерального бюджета на 01.01.2019 г., потребность в котором подтверждена | GG7: Предусмотрено ср-в на т.г всего | GH7: федерального бюджета | GI7: бюджета субъекта Российской Федерации | GJ7: Получено из федерального бюджета в текущем году на отчетную дату | GK7: Восстановлено средств федерального бюджета с начала т.г. по различным основаниям | GL7: Подтверждение восстановления | GM7: Пречислено на отчетную дату всего | GN7: федерального бюджета | GO7: в т.с. За счет остатка | GP7: бюджета субъекта Российской Федерации | GQ7: Фактический уровень финансирования | GR7: Возвращено в федеральный бюджет в текущем году на отчетную дату | GS7: Остаток средств ф.б на лиц. Счетах | GT7: Кассовые расходы на текущую дату | GU7: Прогноз остатков средств федерального бюджета на 31 декабря т.г. | GV7: Лимит по распоряжению | GW7: Доведено РБС | GX7: Остаток средств федерального бюджета на 01.01.2019 г., потребность в котором подтверждена | GY7: Предусмотрено ср-в на т.г всего | GZ7: федерального бюджета | HA7: бюджета субъекта Российской Федерации | HB7: Получено из федерального бюджета в текущем году на отчетную дату | HC7: Восстановлено средств федерального бюджета с начала т.г. по различным основаниям | HD7: Подтверждение восстановления | HE7: Пречислено на отчетную дату всего | HF7: федерального бюджета | HG7: в т.с. За счет остатка | HH7: бюджета субъекта Российской Федерации | HI7: Фактический уровень финансирования | HJ7: Возвращено в федеральный бюджет в текущем году на отчетную дату | HK7: Остаток средств ф.б на лиц. Счетах | HL7: Кассовые расходы на текущую дату | HM7: Прогноз остатков средств федерального бюджета на 31 декабря т.г. | HN7: Лимит по распоряжению | HO7: Доведено РБС | HP7: Остаток средств федерального бюджета на 01.01.2019 г., потребность в котором подтверждена | HQ7: Предусмотрено ср-в на т.г всего | HR7: федерального бюджета | HS7: бюджета субъекта Российской Федерации | HT7: Получено из федерального бюджета в текущем году на отчетную дату | HU7: Восстановлено средств федерального бюджета с начала т.г. по различным основаниям | HV7: Подтверждение восстановления | HW7: Пречислено на отчетную дату всего | HX7: федерального бюджета | HY7: в т.с. За счет остатка | HZ7: бюджета субъекта Российской Федерации | IA7: Фактический уровень финансирования | IB7: Возвращено в федеральный бюджет в текущем году на отчетную дату | IC7: Остаток средств ф.б на лиц. Счетах | ID7: Кассовые расходы на текущую дату | IE7: Прогноз остатков средств федерального бюджета на 31 декабря т.г. | IF7: Лимит по распоряжению | IG7: Доведено РБС | IH7: Остаток средств федерального бюджета на 01.01.2019 г., потребность в котором подтверждена | II7: Предусмотрено ср-в на т.г всего | IJ7: федерального бюджета | IK7: бюджета субъекта Российской Федерации | IL7: Получено из федерального бюджета в текущем году на отчетную дату | IM7: Восстановлено средств федерального бюджета с начала т.г. по различным основаниям | IN7: Подтверждение восстановления | IO7: Пречислено на отчетную дату всего | IP7: федерального бюджета | IQ7: в т.с. За счет остатка | IR7: бюджета субъекта Российской Федерации | IS7: Фактический уровень финансирования | IT7: Возвращено в федеральный бюджет в текущем году на отчетную дату | IU7: Остаток средств ф.б на лиц. Счетах | IV7: Кассовые расходы на текущую дату | IW7: Прогноз остатков средств федерального бюджета на 31 декабря т.г. | IX7: Лимит по распоряжению | IY7: Доведено РБС | IZ7: Остаток средств федерального бюджета на 01.01.2019 г., потребность в котором подтверждена | JA7: Предусмотрено ср-в на т.г всего | JB7: федерального бюджета | JC7: бюджета субъекта Российской Федерации | JD7: Получено из федерального бюджета в текущем году на отчетную дату | JE7: Восстановлено средств федерального бюджета с начала т.г. по различным основаниям | JF7: Подтверждение восстановления | JG7: Пречислено на отчетную дату всего | JH7: федерального бюджета | JI7: в т.с. За счет остатка | JJ7: бюджета субъекта Российской Федерации | JK7: Фактический уровень финансирования | JL7: Возвращено в федеральный бюджет в текущем году на отчетную дату | JM7: Остаток средств ф.б на лиц. Счетах | JN7: Кассовые расходы на текущую дату | JO7: Прогноз остатков средств федерального бюджета на 31 декабря т.г. | JP7: Лимит по распоряжению | JQ7: Доведено РБС | JR7: Остаток средств федерального бюджета на 01.01.2019 г., потребность в котором подтверждена | JS7: Предусмотрено ср-в на т.г всего | JT7: федерального бюджета | JU7: бюджета субъекта Российской Федерации | JV7: Получено из федерального бюджета в текущем году на отчетную дату | JW7: Восстановлено средств федерального бюджета с начала т.г. по различным основаниям | JX7: Подтверждение восстановления | JY7: Пречислено на отчетную дату всего | JZ7: федерального бюджета | KA7: в т.с. За счет остатка | KB7: бюджета субъекта Российской Федерации | KC7: Фактический уровень финансирования | KD7: Возвращено в федеральный бюджет в текущем году на отчетную дату | KE7: Остаток средств ф.б на лиц. Счетах | KF7: Кассовые расходы на текущую дату | KG7: Прогноз остатков средств федерального бюджета на 31 декабря т.г. | KH7: Лимит по распоряжению | KI7: Доведено РБС | KJ7: Остаток средств федерального бюджета на 01.01.2019 г., потребность в котором подтверждена | KK7: Предусмотрено ср-в на т.г всего | KL7: федерального бюджета | KM7: бюджета субъекта Российской Федерации | KN7: Получено из федерального бюджета в текущем году на отчетную дату | KO7: Восстановлено средств федерального бюджета с начала т.г. по различным основаниям | KP7: Подтверждение восстановления | KQ7: Пречислено на отчетную дату всего | KR7: федерального бюджета | KS7: в т.с. За счет остатка | KT7: бюджета субъекта Российской Федерации | KU7: Фактический уровень финансирования | KV7: Возвращено в федеральный бюджет в текущем году на отчетную дату | KW7: Остаток средств ф.б на лиц. Счетах | KX7: Кассовые расходы на текущую дату | KY7: Прогноз остатков средств федерального бюджета на 31 декабря т.г. | KZ7: Лимит по распоряжению | LA7: Доведено РБС | LB7: Остаток средств федерального бюджета на 01.01.2019 г., потребность в котором подтверждена | LC7: Предусмотрено ср-в на т.г всего | LD7: федерального бюджета | LE7: бюджета субъекта Российской Федерации | LF7: Получено из федерального бюджета в текущем году на отчетную дату | LG7: Восстановлено средств федерального бюджета с начала т.г. по различным основаниям | LH7: Подтверждение восстановления | LI7: Пречислено на отчетную дату всего | LJ7: федерального бюджета | LK7: в т.с. За счет остатка | LL7: бюджета субъекта Российской Федерации | LM7: Фактический уровень финансирования | LN7: Возвращено в федеральный бюджет в текущем году на отчетную дату | LO7: Остаток средств ф.б на лиц. Счетах | LP7: Кассовые расходы на текущую дату | LQ7: Прогноз остатков средств федерального бюджета на 31 декабря т.г. | LR7: Лимит по распоряжению | LS7: Доведено РБС | LT7: Остаток средств федерального бюджета на 01.01.2019 г., потребность в котором подтверждена | LU7: Предусмотрено ср-в на т.г всего | LV7: федерального бюджета | LW7: бюджета субъекта Российской Федерации | LX7: Получено из федерального бюджета в текущем году на отчетную дату | LY7: Восстановлено средств федерального бюджета с начала т.г. по различным основаниям | LZ7: Подтверждение восстановления | MA7: Пречислено на отчетную дату всего | MB7: федерального бюджета | MC7: в т.с. За счет остатка | MD7: бюджета субъекта Российской Федерации | ME7: Фактический уровень финансирования | MF7: Возвращено в федеральный бюджет в текущем году на отчетную дату | MG7: Остаток средств ф.б на лиц. Счетах | MH7: Кассовые расходы на текущую дату | MI7: Прогноз остатков средств федерального бюджета на 31 декабря т.г. | MJ7: Лимит по распоряжению | MK7: Доведено РБС | ML7: Остаток средств федерального бюджета на 01.01.2019 г., потребность в котором подтверждена | MM7: Предусмотрено ср-в на т.г всего | MN7: федерального бюджета | MO7: бюджета субъекта Российской Федерации | MP7: Получено из федерального бюджета в текущем году на отчетную дату | MQ7: Восстановлено средств федерального бюджета с начала т.г. по различным основаниям | MR7: Подтверждение восстановления | MS7: Пречислено на отчетную дату всего | MT7: федерального бюджета | MU7: в т.с. За счет остатка | MV7: бюджета субъекта Российской Федерации | MW7: Фактический уровень финансирования | MX7: Возвращено в федеральный бюджет в текущем году на отчетную дату | MY7: Остаток средств ф.б на лиц. Счетах | MZ7: Кассовые расходы на текущую дату | NA7: Прогноз остатков средств федерального бюджета на 31 декабря т.г. | NB7: Лимит по распоряжению | NC7: Доведено РБС | ND7: Остаток средств федерального бюджета на 01.01.2019 г., потребность в котором подтверждена | NE7: Предусмотрено ср-в на т.г всего | NF7: федерального бюджета | NG7: бюджета субъекта Российской Федерации | NH7: Получено из федерального бюджета в текущем году на отчетную дату | NI7: Восстановлено средств федерального бюджета с начала т.г. по различным основаниям | NJ7: Подтверждение восстановления | NK7: Пречислено на отчетную дату всего | NL7: федерального бюджета | NM7: в т.с. За счет остатка | NN7: бюджета субъекта Российской Федерации | NO7: Фактический уровень финансирования | NP7: Возвращено в федеральный бюджет в текущем году на отчетную дату | NQ7: Остаток средств ф.б на лиц. Счетах | NR7: Кассовые расходы на текущую дату | NS7: Прогноз остатков средств федерального бюджета на 31 декабря т.г. | NT7: Лимит по распоряжению | NU7: Доведено РБС | NV7: Остаток средств федерального бюджета на 01.01.2019 г., потребность в котором подтверждена | NW7: Предусмотрено ср-в на т.г всего | NX7: федерального бюджета | NY7: бюджета субъекта Российской Федерации | NZ7: Получено из федерального бюджета в текущем году на отчетную дату | OA7: Восстановлено средств федерального бюджета с начала т.г. по различным основаниям | OB7: Подтверждение восстановления | OC7: Пречислено на отчетную дату всего | OD7: федерального бюджета | OE7: в т.с. За счет остатка | OF7: бюджета субъекта Российской Федерации | OG7: Фактический уровень финансирования | OH7: Возвращено в федеральный бюджет в текущем году на отчетную дату | OI7: Остаток средств ф.б на лиц. Счетах | OJ7: Кассовые расходы на текущую дату | OK7: Прогноз остатков средств федерального бюджета на 31 декабря т.г. | OL7: Лимит по распоряжению | OM7: Доведено РБС | ON7: Остаток средств федерального бюджета на 01.01.2019 г., потребность в котором подтверждена | OO7: Предусмотрено ср-в на т.г всего | OP7: федерального бюджета | OQ7: бюджета субъекта Российской Федерации | OR7: Получено из федерального бюджета в текущем году на отчетную дату | OS7: Восстановлено средств федерального бюджета с начала т.г. по различным основаниям | OT7: Подтверждение восстановления | OU7: Пречислено на отчетную дату всего | OV7: федерального бюджета | OW7: в т.с. За счет остатка | OX7: бюджета субъекта Российской Федерации | OY7: Фактический уровень финансирования | OZ7: Возвращено в федеральный бюджет в текущем году на отчетную дату | PA7: Остаток средств ф.б на лиц. Счетах | PB7: Кассовые расходы на текущую дату | PC7: Прогноз остатков средств федерального бюджета на 31 декабря т.г. | PD7: Лимит по распоряжению | PE7: Доведено РБС | PF7: Остаток средств федерального бюджета на 01.01.2019 г., потребность в котором подтверждена | PG7: Предусмотрено ср-в на т.г всего | PH7: федерального бюджета | PI7: бюджета субъекта Российской Федерации | PJ7: Получено из федерального бюджета в текущем году на отчетную дату | PK7: Восстановлено средств федерального бюджета с начала т.г. по различным основаниям | PL7: Подтверждение восстановления | PM7: Пречислено на отчетную дату всего | PN7: федерального бюджета | PO7: в т.с. За счет остатка | PP7: бюджета субъекта Российской Федерации | PQ7: Фактический уровень финансирования | PR7: Возвращено в федеральный бюджет в текущем году на отчетную дату | PS7: Остаток средств ф.б на лиц. Счетах | PT7: Кассовые расходы на текущую дату | PU7: Прогноз остатков средств федерального бюджета на 31 декабря т.г. | PV7: Лимит по распоряжению | PW7: Доведено РБС | PX7: Остаток средств федерального бюджета на 01.01.2019 г., потребность в котором подтверждена | PY7: Предусмотрено ср-в на т.г всего | PZ7: федерального бюджета | QA7: бюджета субъекта Российской Федерации | QB7: Получено из федерального бюджета в текущем году на отчетную дату | QC7: Восстановлено средств федерального бюджета с начала т.г. по различным основаниям | QD7: Подтверждение восстановления | QE7: Пречислено на отчетную дату всего | QF7: федерального бюджета | QG7: в т.с. За счет остатка | QH7: бюджета субъекта Российской Федерации | QI7: Фактический уровень финансирования | QJ7: Возвращено в федеральный бюджет в текущем году на отчетную дату | QK7: Остаток средств ф.б на лиц. Счетах | QL7: Кассовые расходы на текущую дату | QM7: Прогноз остатков средств федерального бюджета на 31 декабря т.г. | QN7: Лимит по распоряжению | QO7: Доведено РБС | QP7: Остаток средств федерального бюджета на 01.01.2019 г., потребность в котором подтверждена | QQ7: Предусмотрено ср-в на т.г всего | QR7: федерального бюджета | QS7: бюджета субъекта Российской Федерации | QT7: Получено из федерального бюджета в текущем году на отчетную дату | QU7: Восстановлено средств федерального бюджета с начала т.г. по различным основаниям | QV7: Подтверждение восстановления | QW7: Пречислено на отчетную дату всего | QX7: федерального бюджета | QY7: в т.с. За счет остатка | QZ7: бюджета субъекта Российской Федерации | RA7: Фактический уровень финансирования | RB7: Возвращено в федеральный бюджет в текущем году на отчетную дату | RC7: Остаток средств ф.б на лиц. Счетах | RD7: Кассовые расходы на текущую дату | RE7: Прогноз остатков средств федерального бюджета на 31 декабря т.г. | RF7: Лимит по распоряжению | RG7: Доведено РБС | RH7: Остаток средств федерального бюджета на 01.01.2019 г., потребность в котором подтверждена | RI7: Предусмотрено ср-в на т.г всего | RJ7: федерального бюджета | RK7: бюджета субъекта Российской Федерации | RL7: Получено из федерального бюджета в текущем году на отчетную дату | RM7: Восстановлено средств федерального бюджета с начала т.г. по различным основаниям | RN7: Подтверждение восстановления | RO7: Пречислено на отчетную дату всего | RP7: федерального бюджета | RQ7: в т.с. За счет остатка | RR7: бюджета субъекта Российской Федерации | RS7: Фактический уровень финансирования | RT7: Возвращено в федеральный бюджет в текущем году на отчетную дату | RU7: Остаток средств ф.б на лиц. Счетах | RV7: Кассовые расходы на текущую дату | RW7: Прогноз остатков средств федерального бюджета на 31 декабря т.г. | RX7: Лимит по распоряжению | RY7: Доведено РБС | RZ7: Остаток средств федерального бюджета на 01.01.2019 г., потребность в котором подтверждена | SA7: Предусмотрено ср-в на т.г всего | SB7: федерального бюджета | SC7: бюджета субъекта Российской Федерации | SD7: Получено из федерального бюджета в текущем году на отчетную дату | SE7: Восстановлено средств федерального бюджета с начала т.г. по различным основаниям | SF7: Подтверждение восстановления | SG7: Пречислено на отчетную дату всего | SH7: федерального бюджета | SI7: в т.с. За счет остатка | SJ7: бюджета субъекта Российской Федерации | SK7: Фактический уровень финансирования | SL7: Возвращено в федеральный бюджет в текущем году на отчетную дату | SM7: Остаток средств ф.б на лиц. Счетах | SN7: Кассовые расходы на текущую дату | SO7: Прогноз остатков средств федерального бюджета на 31 декабря т.г. | SP7: Лимит по распоряжению | SQ7: Доведено РБС | SR7: Остаток средств федерального бюджета на 01.01.2019 г., потребность в котором подтверждена | SS7: Предусмотрено ср-в на т.г всего | ST7: федерального бюджета | SU7: бюджета субъекта Российской Федерации | SV7: Получено из федерального бюджета в текущем году на отчетную дату | SW7: Восстановлено средств федерального бюджета с начала т.г. по различным основаниям | SX7: Подтверждение восстановления | SY7: Пречислено на отчетную дату всего | SZ7: федерального бюджета | TA7: в т.с. За счет остатка | TB7: бюджета субъекта Российской Федерации | TC7: Фактический уровень финансирования | TD7: Возвращено в федеральный бюджет в текущем году на отчетную дату | TE7: Остаток средств ф.б на лиц. Счетах | TF7: Кассовые расходы на текущую дату | TG7: Прогноз остатков средств федерального бюджета на 31 декабря т.г. | TH7: Лимит по распоряжению | TI7: Доведено РБС | TJ7: Остаток средств федерального бюджета на 01.01.2019 г., потребность в котором подтверждена | TK7: Предусмотрено ср-в на т.г всего | TL7: федерального бюджета | TM7: бюджета субъекта Российской Федерации | TN7: Получено из федерального бюджета в текущем году на отчетную дату | TO7: Восстановлено средств федерального бюджета с начала т.г. по различным основаниям | TP7: Подтверждение восстановления | TQ7: Пречислено на отчетную дату всего | TR7: федерального бюджета | TS7: в т.с. За счет остатка | TT7: бюджета субъекта Российской Федерации | TU7: Фактический уровень финансирования | TV7: Возвращено в федеральный бюджет в текущем году на отчетную дату | TW7: Остаток средств ф.б на лиц. Счетах | TX7: Кассовые расходы на текущую дату | TY7: Прогноз остатков средств федерального бюджета на 31 декабря т.г. | TZ7: Лимит по распоряжению | UA7: Доведено РБС | UB7: Остаток средств федерального бюджета на 01.01.2019 г., потребность в котором подтверждена | UC7: Предусмотрено ср-в на т.г всего | UD7: федерального бюджета | UE7: бюджета субъекта Российской Федерации | UF7: Получено из федерального бюджета в текущем году на отчетную дату | UG7: Восстановлено средств федерального бюджета с начала т.г. по различным основаниям | UH7: Подтверждение восстановления | UI7: Пречислено на отчетную дату всего | UJ7: федерального бюджета | UK7: в т.с. За счет остатка | UL7: бюджета субъекта Российской Федерации | UM7: Фактический уровень финансирования | UN7: Возвращено в федеральный бюджет в текущем году на отчетную дату | UO7: Остаток средств ф.б на лиц. Счетах | UP7: Кассовые расходы на текущую дату | UQ7: Прогноз остатков средств федерального бюджета на 31 декабря т.г. | UR7: Лимит по распоряжению | US7: Доведено РБС
D13: 37776П | E13: 37776К | F13: 1020 | G13: 1022 | H13: =H5&"04" -> 3704 | I13: =H5&"05" -> 3705 | J13: =H5&"06" -> 3706 | K13: =H5&"07" -> 3707 | L13: =H5&"08" -> 3708 | M13: =H5&"09" -> 3709 | N13: =H5&"52" -> 3752 | O13: =H5&"10" -> 3710 | P13: =H5&"11" -> 3711 | Q13: =H5&"12" -> 3712 | R13: =H5&"13" -> 3713 | S13: =H5&"14" -> 3714 | T13: =H5&"15" -> 3715 | U13: =H5&"16" -> 3716 | V13: =H5&"21" -> 3721 | W13: =H5&"19" -> 3719 | X13: =H5&"51" -> 3751 | Y13: =H5&"23" -> 3723 | Z13: =Z5&"04" -> 6204 | AA13: =Z5&"05" -> 6205 | AB13: =Z5&"06" -> 6206 | AC13: =Z5&"07" -> 6207 | AD13: =Z5&"08" -> 6208 | AE13: =Z5&"09" -> 6209 | AF13: =Z5&"52" -> 6252 | AG13: =Z5&"10" -> 6210 | AH13: =Z5&"11" -> 6211 | AI13: =Z5&"12" -> 6212 | AJ13: =Z5&"13" -> 6213 | AK13: =Z5&"14" -> 6214 | AL13: =Z5&"15" -> 6215 | AM13: =Z5&"16" -> 6216 | AN13: =Z5&"21" -> 6221 | AO13: =Z5&"19" -> 6219 | AP13: =Z5&"51" -> 6251 | AQ13: =Z5&"23" -> 6223 | AR13: =AR5&"04" -> 4504 | AS13: =AR5&"05" -> 4505 | AT13: =AR5&"06" -> 4506 | AU13: =AR5&"07" -> 4507 | AV13: =AR5&"08" -> 4508 | AW13: =AR5&"09" -> 4509 | AX13: =AR5&"52" -> 4552 | AY13: =AR5&"10" -> 4510 | AZ13: =AR5&"11" -> 4511 | BA13: =AR5&"12" -> 4512 | BB13: =AR5&"13" -> 4513 | BC13: =AR5&"14" -> 4514 | BD13: =AR5&"15" -> 4515 | BE13: =AR5&"16" -> 4516 | BF13: =AR5&"21" -> 4521 | BG13: =AR5&"19" -> 4519 | BH13: =AR5&"51" -> 4551 | BI13: =AR5&"23" -> 4523 | BJ13: =BJ5&"04" -> КОЛ06104 | BK13: =BJ5&"05" -> КОЛ06105 | BL13: =BJ5&"06" -> КОЛ06106 | BM13: =BJ5&"07" -> КОЛ06107 | BN13: =BJ5&"08" -> КОЛ06108 | BO13: =BJ5&"09" -> КОЛ06109 | BP13: =BJ5&"52" -> КОЛ06152 | BQ13: =BJ5&"10" -> КОЛ06110 | BR13: =BJ5&"11" -> КОЛ06111 | BS13: =BJ5&"12" -> КОЛ06112 | BT13: =BJ5&"13" -> КОЛ06113 | BU13: =BJ5&"14" -> КОЛ06114 | BV13: =BJ5&"15" -> КОЛ06115 | BW13: =BJ5&"16" -> КОЛ06116 | BX13: =BJ5&"21" -> КОЛ06121 | BY13: =BJ5&"19" -> КОЛ06119 | BZ13: =BJ5&"51" -> КОЛ06151 | CA13: =BJ5&"23" -> КОЛ06123 | CB13: =CB5&"04" -> 1704 | CC13: =CB5&"05" -> 1705 | CD13: =CB5&"06" -> 1706 | CE13: =CB5&"07" -> 1707 | CF13: =CB5&"08" -> 1708 | CG13: =CB5&"09" -> 1709 | CH13: =CB5&"52" -> 1752 | CI13: =CB5&"10" -> 1710 | CJ13: =CB5&"11" -> 1711 | CK13: =CB5&"12" -> 1712 | CL13: =CB5&"13" -> 1713 | CM13: =CB5&"14" -> 1714 | CN13: =CB5&"15" -> 1715 | CO13: =CB5&"16" -> 1716 | CP13: =CB5&"21" -> 1721 | CQ13: =CB5&"19" -> 1719 | CR13: =CB5&"51" -> 1751 | CS13: =CB5&"23" -> 1723 | CT13: =CT5&"04" -> КОЛ01704 | CU13: =CT5&"05" -> КОЛ01705 | CV13: =CT5&"06" -> КОЛ01706 | CW13: =CT5&"07" -> КОЛ01707 | CX13: =CT5&"08" -> КОЛ01708 | CY13: =CT5&"09" -> КОЛ01709 | CZ13: =CT5&"52" -> КОЛ01752 | DA13: =CT5&"10" -> КОЛ01710 | DB13: =CT5&"11" -> КОЛ01711 | DC13: =CT5&"12" -> КОЛ01712 | DD13: =CT5&"13" -> КОЛ01713 | DE13: =CT5&"14" -> КОЛ01714 | DF13: =CT5&"15" -> КОЛ01715 | DG13: =CT5&"16" -> КОЛ01716 | DH13: =CT5&"21" -> КОЛ01721 | DI13: =CT5&"19" -> КОЛ01719 | DJ13: =CT5&"51" -> КОЛ01751 | DK13: =CT5&"23" -> КОЛ01723 | DL13: =DL5&"04" -> 5904 | DM13: =DL5&"05" -> 5905 | DN13: =DL5&"06" -> 5906 | DO13: =DL5&"07" -> 5907 | DP13: =DL5&"08" -> 5908 | DQ13: =DL5&"09" -> 5909 | DR13: =DL5&"52" -> 5952 | DS13: =DL5&"10" -> 5910 | DT13: =DL5&"11" -> 5911 | DU13: =DL5&"12" -> 5912 | DV13: =DL5&"13" -> 5913 | DW13: =DL5&"14" -> 5914 | DX13: =DL5&"15" -> 5915 | DY13: =DL5&"16" -> 5916 | DZ13: =DL5&"21" -> 5921 | EA13: =DL5&"19" -> 5919 | EB13: =DL5&"51" -> 5951 | EC13: =DL5&"23" -> 5923 | ED13: =ED5&"04" -> КОЛ03704 | EE13: =ED5&"05" -> КОЛ03705 | EF13: =ED5&"06" -> КОЛ03706 | EG13: =ED5&"07" -> КОЛ03707 | EH13: =ED5&"08" -> КОЛ03708 | EI13: =ED5&"09" -> КОЛ03709 | EJ13: =ED5&"52" -> КОЛ03752 | EK13: =ED5&"10" -> КОЛ03710 | EL13: =ED5&"11" -> КОЛ03711 | EM13: =ED5&"12" -> КОЛ03712 | EN13: =ED5&"13" -> КОЛ03713 | EO13: =ED5&"14" -> КОЛ03714 | EP13: =ED5&"15" -> КОЛ03715 | EQ13: =ED5&"16" -> КОЛ03716 | ER13: =ED5&"21" -> КОЛ03721 | ES13: =ED5&"19" -> КОЛ03719 | ET13: =ED5&"51" -> КОЛ03751 | EU13: =ED5&"23" -> КОЛ03723 | EV13: =EV5&"04" -> 6104 | EW13: =EV5&"05" -> 6105 | EX13: =EV5&"06" -> 6106 | EY13: =EV5&"07" -> 6107 | EZ13: =EV5&"08" -> 6108 | FA13: =EV5&"09" -> 6109 | FB13: =EV5&"52" -> 6152 | FC13: =EV5&"10" -> 6110 | FD13: =EV5&"11" -> 6111 | FE13: =EV5&"12" -> 6112 | FF13: =EV5&"13" -> 6113 | FG13: =EV5&"14" -> 6114 | FH13: =EV5&"15" -> 6115 | FI13: =EV5&"16" -> 6116 | FJ13: =EV5&"21" -> 6121 | FK13: =EV5&"19" -> 6119 | FL13: =EV5&"51" -> 6151 | FM13: =EV5&"23" -> 6123 | FN13: =FN5&"04" -> КОЛ04904 | FO13: =FN5&"05" -> КОЛ04905 | FP13: =FN5&"06" -> КОЛ04906 | FQ13: =FN5&"07" -> КОЛ04907 | FR13: =FN5&"08" -> КОЛ04908 | FS13: =FN5&"09" -> КОЛ04909 | FT13: =FN5&"52" -> КОЛ04952 | FU13: =FN5&"10" -> КОЛ04910 | FV13: =FN5&"11" -> КОЛ04911 | FW13: =FN5&"12" -> КОЛ04912 | FX13: =FN5&"13" -> КОЛ04913 | FY13: =FN5&"14" -> КОЛ04914 | FZ13: =FN5&"15" -> КОЛ04915 | GA13: =FN5&"16" -> КОЛ04916 | GB13: =FN5&"21" -> КОЛ04921 | GC13: =FN5&"19" -> КОЛ04919 | GD13: =FN5&"51" -> КОЛ04951 | GE13: =FN5&"23" -> КОЛ04923 | GF13: =GF5&"04" -> 5104 | GG13: =GF5&"05" -> 5105 | GH13: =GF5&"06" -> 5106 | GI13: =GF5&"07" -> 5107 | GJ13: =GF5&"08" -> 5108 | GK13: =GF5&"09" -> 5109 | GL13: =GF5&"52" -> 5152 | GM13: =GF5&"10" -> 5110 | GN13: =GF5&"11" -> 5111 | GO13: =GF5&"12" -> 5112 | GP13: =GF5&"13" -> 5113 | GQ13: =GF5&"14" -> 5114 | GR13: =GF5&"15" -> 5115 | GS13: =GF5&"16" -> 5116 | GT13: =GF5&"21" -> 5121 | GU13: =GF5&"19" -> 5119 | GV13: =GF5&"51" -> 5151 | GW13: =GF5&"23" -> 5123 | GX13: =GX5&"04" -> КОЛ05104 | GY13: =GX5&"05" -> КОЛ05105 | GZ13: =GX5&"06" -> КОЛ05106 | HA13: =GX5&"07" -> КОЛ05107 | HB13: =GX5&"08" -> КОЛ05108 | HC13: =GX5&"09" -> КОЛ05109 | HD13: =GX5&"52" -> КОЛ05152 | HE13: =GX5&"10" -> КОЛ05110 | HF13: =GX5&"11" -> КОЛ05111 | HG13: =GX5&"12" -> КОЛ05112 | HH13: =GX5&"13" -> КОЛ05113 | HI13: =GX5&"14" -> КОЛ05114 | HJ13: =GX5&"15" -> КОЛ05115 | HK13: =GX5&"16" -> КОЛ05116 | HL13: =GX5&"21" -> КОЛ05121 | HM13: =GX5&"19" -> КОЛ05119 | HN13: =GX5&"51" -> КОЛ05151 | HO13: =GX5&"23" -> КОЛ05123 | HP13: =HP5&"04" -> 5204 | HQ13: =HP5&"05" -> 5205 | HR13: =HP5&"06" -> 5206 | HS13: =HP5&"07" -> 5207 | HT13: =HP5&"08" -> 5208 | HU13: =HP5&"09" -> 5209 | HV13: =HP5&"52" -> 5252 | HW13: =HP5&"10" -> 5210 | HX13: =HP5&"11" -> 5211 | HY13: =HP5&"12" -> 5212 | HZ13: =HP5&"13" -> 5213 | IA13: =HP5&"14" -> 5214 | IB13: =HP5&"15" -> 5215 | IC13: =HP5&"16" -> 5216 | ID13: =HP5&"21" -> 5221 | IE13: =HP5&"19" -> 5219 | IF13: =HP5&"51" -> 5251 | IG13: =HP5&"23" -> 5223 | IH13: =IH5&"04" -> КОЛ05204 | II13: =IH5&"05" -> КОЛ05205 | IJ13: =IH5&"06" -> КОЛ05206 | IK13: =IH5&"07" -> КОЛ05207 | IL13: =IH5&"08" -> КОЛ05208 | IM13: =IH5&"09" -> КОЛ05209 | IN13: =IH5&"52" -> КОЛ05252 | IO13: =IH5&"10" -> КОЛ05210 | IP13: =IH5&"11" -> КОЛ05211 | IQ13: =IH5&"12" -> КОЛ05212 | IR13: =IH5&"13" -> КОЛ05213 | IS13: =IH5&"14" -> КОЛ05214 | IT13: =IH5&"15" -> КОЛ05215 | IU13: =IH5&"16" -> КОЛ05216 | IV13: =IH5&"21" -> КОЛ05221 | IW13: =IH5&"19" -> КОЛ05219 | IX13: =IH5&"51" -> КОЛ05251 | IY13: =IH5&"23" -> КОЛ05223 | IZ13: =IZ5&"04" -> 5304 | JA13: =IZ5&"05" -> 5305 | JB13: =IZ5&"06" -> 5306 | JC13: =IZ5&"07" -> 5307 | JD13: =IZ5&"08" -> 5308 | JE13: =IZ5&"09" -> 5309 | JF13: =IZ5&"52" -> 5352 | JG13: =IZ5&"10" -> 5310 | JH13: =IZ5&"11" -> 5311 | JI13: =IZ5&"12" -> 5312 | JJ13: =IZ5&"13" -> 5313 | JK13: =IZ5&"14" -> 5314 | JL13: =IZ5&"15" -> 5315 | JM13: =IZ5&"16" -> 5316 | JN13: =IZ5&"21" -> 5321 | JO13: =IZ5&"19" -> 5319 | JP13: =IZ5&"51" -> 5351 | JQ13: =IZ5&"23" -> 5323 | JR13: =JR5&"04" -> КОЛ05304 | JS13: =JR5&"05" -> КОЛ05305 | JT13: =JR5&"06" -> КОЛ05306 | JU13: =JR5&"07" -> КОЛ05307 | JV13: =JR5&"08" -> КОЛ05308 | JW13: =JR5&"09" -> КОЛ05309 | JX13: =JR5&"52" -> КОЛ05352 | JY13: =JR5&"10" -> КОЛ05310 | JZ13: =JR5&"11" -> КОЛ05311 | KA13: =JR5&"12" -> КОЛ05312 | KB13: =JR5&"13" -> КОЛ05313 | KC13: =JR5&"14" -> КОЛ05314 | KD13: =JR5&"15" -> КОЛ05315 | KE13: =JR5&"16" -> КОЛ05316 | KF13: =JR5&"21" -> КОЛ05321 | KG13: =JR5&"19" -> КОЛ05319 | KH13: =JR5&"51" -> КОЛ05351 | KI13: =JR5&"23" -> КОЛ05323 | KJ13: =KJ5&"04" -> 5404 | KK13: =KJ5&"05" -> 5405 | KL13: =KJ5&"06" -> 5406 | KM13: =KJ5&"07" -> 5407 | KN13: =KJ5&"08" -> 5408 | KO13: =KJ5&"09" -> 5409 | KP13: =KJ5&"52" -> 5452 | KQ13: =KJ5&"10" -> 5410 | KR13: =KJ5&"11" -> 5411 | KS13: =KJ5&"12" -> 5412 | KT13: =KJ5&"13" -> 5413 | KU13: =KJ5&"14" -> 5414 | KV13: =KJ5&"15" -> 5415 | KW13: =KJ5&"16" -> 5416 | KX13: =KJ5&"21" -> 5421 | KY13: =KJ5&"19" -> 5419 | KZ13: =KJ5&"51" -> 5451 | LA13: =KJ5&"23" -> 5423 | LB13: =LB5&"04" -> КОЛ05404 | LC13: =LB5&"05" -> КОЛ05405 | LD13: =LB5&"06" -> КОЛ05406 | LE13: =LB5&"07" -> КОЛ05407 | LF13: =LB5&"08" -> КОЛ05408 | LG13: =LB5&"09" -> КОЛ05409 | LH13: =LB5&"52" -> КОЛ05452 | LI13: =LB5&"10" -> КОЛ05410 | LJ13: =LB5&"11" -> КОЛ05411 | LK13: =LB5&"12" -> КОЛ05412 | LL13: =LB5&"13" -> КОЛ05413 | LM13: =LB5&"14" -> КОЛ05414 | LN13: =LB5&"15" -> КОЛ05415 | LO13: =LB5&"16" -> КОЛ05416 | LP13: =LB5&"21" -> КОЛ05421 | LQ13: =LB5&"19" -> КОЛ05419 | LR13: =LB5&"51" -> КОЛ05451 | LS13: =LB5&"23" -> КОЛ05423 | LT13: =LT5&"04" -> 5804 | LU13: =LT5&"05" -> 5805 | LV13: =LT5&"06" -> 5806 | LW13: =LT5&"07" -> 5807 | LX13: =LT5&"08" -> 5808 | LY13: =LT5&"09" -> 5809 | LZ13: =LT5&"52" -> 5852 | MA13: =LT5&"10" -> 5810 | MB13: =LT5&"11" -> 5811 | MC13: =LT5&"12" -> 5812 | MD13: =LT5&"13" -> 5813 | ME13: =LT5&"14" -> 5814 | MF13: =LT5&"15" -> 5815 | MG13: =LT5&"16" -> 5816 | MH13: =LT5&"21" -> 5821 | MI13: =LT5&"19" -> 5819 | MJ13: =LT5&"51" -> 5851 | MK13: =LT5&"23" -> 5823 | ML13: =ML5&"04" -> КОЛ05504 | MM13: =ML5&"05" -> КОЛ05505 | MN13: =ML5&"06" -> КОЛ05506 | MO13: =ML5&"07" -> КОЛ05507 | MP13: =ML5&"08" -> КОЛ05508 | MQ13: =ML5&"09" -> КОЛ05509 | MR13: =ML5&"52" -> КОЛ05552 | MS13: =ML5&"10" -> КОЛ05510 | MT13: =ML5&"11" -> КОЛ05511 | MU13: =ML5&"12" -> КОЛ05512 | MV13: =ML5&"13" -> КОЛ05513 | MW13: =ML5&"14" -> КОЛ05514 | MX13: =ML5&"15" -> КОЛ05515 | MY13: =ML5&"16" -> КОЛ05516 | MZ13: =ML5&"21" -> КОЛ05521 | NA13: =ML5&"19" -> КОЛ05519 | NB13: =ML5&"51" -> КОЛ05551 | NC13: =ML5&"23" -> КОЛ05523 | ND13: =ND5&"04" -> 6004 | NE13: =ND5&"05" -> 6005 | NF13: =ND5&"06" -> 6006 | NG13: =ND5&"07" -> 6007 | NH13: =ND5&"08" -> 6008 | NI13: =ND5&"09" -> 6009 | NJ13: =ND5&"52" -> 6052 | NK13: =ND5&"10" -> 6010 | NL13: =ND5&"11" -> 6011 | NM13: =ND5&"12" -> 6012 | NN13: =ND5&"13" -> 6013 | NO13: =ND5&"14" -> 6014 | NP13: =ND5&"15" -> 6015 | NQ13: =ND5&"16" -> 6016 | NR13: =ND5&"21" -> 6021 | NS13: =ND5&"19" -> 6019 | NT13: =ND5&"51" -> 6051 | NU13: =ND5&"23" -> 6023 | NV13: =NV5&"04" -> КОЛ06004 | NW13: =NV5&"05" -> КОЛ06005 | NX13: =NV5&"06" -> КОЛ06006 | NY13: =NV5&"07" -> КОЛ06007 | NZ13: =NV5&"08" -> КОЛ06008 | OA13: =NV5&"09" -> КОЛ06009 | OB13: =NV5&"52" -> КОЛ06052 | OC13: =NV5&"10" -> КОЛ06010 | OD13: =NV5&"11" -> КОЛ06011 | OE13: =NV5&"12" -> КОЛ06012 | OF13: =NV5&"13" -> КОЛ06013 | OG13: =NV5&"14" -> КОЛ06014 | OH13: =NV5&"15" -> КОЛ06015 | OI13: =NV5&"16" -> КОЛ06016 | OJ13: =NV5&"21" -> КОЛ06021 | OK13: =NV5&"19" -> КОЛ06019 | OL13: =NV5&"51" -> КОЛ06051 | OM13: =NV5&"23" -> КОЛ06023 | ON13: =ON5&"04" -> 5704 | OO13: =ON5&"05" -> 5705 | OP13: =ON5&"06" -> 5706 | OQ13: =ON5&"07" -> 5707 | OR13: =ON5&"08" -> 5708 | OS13: =ON5&"09" -> 5709 | OT13: =ON5&"52" -> 5752 | OU13: =ON5&"10" -> 5710 | OV13: =ON5&"11" -> 5711 | OW13: =ON5&"12" -> 5712 | OX13: =ON5&"13" -> 5713 | OY13: =ON5&"14" -> 5714 | OZ13: =ON5&"15" -> 5715 | PA13: =ON5&"16" -> 5716 | PB13: =ON5&"21" -> 5721 | PC13: =ON5&"19" -> 5719 | PD13: =ON5&"51" -> 5751 | PE13: =ON5&"23" -> 5723 | PF13: =PF5&"04" -> 6304 | PG13: =PF5&"05" -> 6305 | PH13: =PF5&"06" -> 6306 | PI13: =PF5&"07" -> 6307 | PJ13: =PF5&"08" -> 6308 | PK13: =PF5&"09" -> 6309 | PL13: =PF5&"52" -> 6352 | PM13: =PF5&"10" -> 6310 | PN13: =PF5&"11" -> 6311 | PO13: =PF5&"12" -> 6312 | PP13: =PF5&"13" -> 6313 | PQ13: =PF5&"14" -> 6314 | PR13: =PF5&"15" -> 6315 | PS13: =PF5&"16" -> 6316 | PT13: =PF5&"21" -> 6321 | PU13: =PF5&"19" -> 6319 | PV13: =PF5&"51" -> 6351 | PW13: =PF5&"23" -> 6323 | PX13: =PX5&"04" -> КОЛ06404 | PY13: =PX5&"05" -> КОЛ06405 | PZ13: =PX5&"06" -> КОЛ06406 | QA13: =PX5&"07" -> КОЛ06407 | QB13: =PX5&"08" -> КОЛ06408 | QC13: =PX5&"09" -> КОЛ06409 | QD13: =PX5&"52" -> КОЛ06452 | QE13: =PX5&"10" -> КОЛ06410 | QF13: =PX5&"11" -> КОЛ06411 | QG13: =PX5&"12" -> КОЛ06412 | QH13: =PX5&"13" -> КОЛ06413 | QI13: =PX5&"14" -> КОЛ06414 | QJ13: =PX5&"15" -> КОЛ06415 | QK13: =PX5&"16" -> КОЛ06416 | QL13: =PX5&"21" -> КОЛ06421 | QM13: =PX5&"19" -> КОЛ06419 | QN13: =PX5&"51" -> КОЛ06451 | QO13: =PX5&"23" -> КОЛ06423 | QP13: =QP5&"04" -> 6504 | QQ13: =QP5&"05" -> 6505 | QR13: =QP5&"06" -> 6506 | QS13: =QP5&"07" -> 6507 | QT13: =QP5&"08" -> 6508 | QU13: =QP5&"09" -> 6509 | QV13: =QP5&"52" -> 6552 | QW13: =QP5&"10" -> 6510 | QX13: =QP5&"11" -> 6511 | QY13: =QP5&"12" -> 6512 | QZ13: =QP5&"13" -> 6513 | RA13: =QP5&"14" -> 6514 | RB13: =QP5&"15" -> 6515 | RC13: =QP5&"16" -> 6516 | RD13: =QP5&"21" -> 6521 | RE13: =QP5&"19" -> 6519 | RF13: =QP5&"51" -> 6551 | RG13: =QP5&"23" -> 6523 | RH13: =RH5&"04" -> КОЛ06604 | RI13: =RH5&"05" -> КОЛ06605 | RJ13: =RH5&"06" -> КОЛ06606 | RK13: =RH5&"07" -> КОЛ06607 | RL13: =RH5&"08" -> КОЛ06608 | RM13: =RH5&"09" -> КОЛ06609 | RN13: =RH5&"52" -> КОЛ06652 | RO13: =RH5&"10" -> КОЛ06610 | RP13: =RH5&"11" -> КОЛ06611 | RQ13: =RH5&"12" -> КОЛ06612 | RR13: =RH5&"13" -> КОЛ06613 | RS13: =RH5&"14" -> КОЛ06614 | RT13: =RH5&"15" -> КОЛ06615 | RU13: =RH5&"16" -> КОЛ06616 | RV13: =RH5&"21" -> КОЛ06621 | RW13: =RH5&"19" -> КОЛ06619 | RX13: =RH5&"51" -> КОЛ06651 | RY13: =RH5&"23" -> КОЛ06623 | RZ13: =RZ5&"04" -> 6704 | SA13: =RZ5&"05" -> 6705 | SB13: =RZ5&"06" -> 6706 | SC13: =RZ5&"07" -> 6707 | SD13: =RZ5&"08" -> 6708 | SE13: =RZ5&"09" -> 6709 | SF13: =RZ5&"52" -> 6752 | SG13: =RZ5&"10" -> 6710 | SH13: =RZ5&"11" -> 6711 | SI13: =RZ5&"12" -> 6712 | SJ13: =RZ5&"13" -> 6713 | SK13: =RZ5&"14" -> 6714 | SL13: =RZ5&"15" -> 6715 | SM13: =RZ5&"16" -> 6716 | SN13: =RZ5&"21" -> 6721 | SO13: =RZ5&"19" -> 6719 | SP13: =RZ5&"51" -> 6751 | SQ13: =RZ5&"23" -> 6723 | SR13: =SR5&"04" -> КОЛ06804 | SS13: =SR5&"05" -> КОЛ06805 | ST13: =SR5&"06" -> КОЛ06806 | SU13: =SR5&"07" -> КОЛ06807 | SV13: =SR5&"08" -> КОЛ06808 | SW13: =SR5&"09" -> КОЛ06809 | SX13: =SR5&"52" -> КОЛ06852 | SY13: =SR5&"10" -> КОЛ06810 | SZ13: =SR5&"11" -> КОЛ06811 | TA13: =SR5&"12" -> КОЛ06812 | TB13: =SR5&"13" -> КОЛ06813 | TC13: =SR5&"14" -> КОЛ06814 | TD13: =SR5&"15" -> КОЛ06815 | TE13: =SR5&"16" -> КОЛ06816 | TF13: =SR5&"21" -> КОЛ06821 | TG13: =SR5&"19" -> КОЛ06819 | TH13: =SR5&"51" -> КОЛ06851 | TI13: =SR5&"23" -> КОЛ06823 | TJ13: =TJ5&"04" -> 6904 | TK13: =TJ5&"05" -> 6905 | TL13: =TJ5&"06" -> 6906 | TM13: =TJ5&"07" -> 6907 | TN13: =TJ5&"08" -> 6908 | TO13: =TJ5&"09" -> 6909 | TP13: =TJ5&"52" -> 6952 | TQ13: =TJ5&"10" -> 6910 | TR13: =TJ5&"11" -> 6911 | TS13: =TJ5&"12" -> 6912 | TT13: =TJ5&"13" -> 6913 | TU13: =TJ5&"14" -> 6914 | TV13: =TJ5&"15" -> 6915 | TW13: =TJ5&"16" -> 6916 | TX13: =TJ5&"21" -> 6921 | TY13: =TJ5&"19" -> 6919 | TZ13: =TJ5&"51" -> 6951 | UA13: =TJ5&"23" -> 6923 | UB13: =UB5&"04" -> КОЛ07004 | UC13: =UB5&"05" -> КОЛ07005 | UD13: =UB5&"06" -> КОЛ07006 | UE13: =UB5&"07" -> КОЛ07007 | UF13: =UB5&"08" -> КОЛ07008 | UG13: =UB5&"09" -> КОЛ07009 | UH13: =UB5&"52" -> КОЛ07052 | UI13: =UB5&"10" -> КОЛ07010 | UJ13: =UB5&"11" -> КОЛ07011 | UK13: =UB5&"12" -> КОЛ07012 | UL13: =UB5&"13" -> КОЛ07013 | UM13: =UB5&"14" -> КОЛ07014 | UN13: =UB5&"15" -> КОЛ07015 | UO13: =UB5&"16" -> КОЛ07016 | UP13: =UB5&"21" -> КОЛ07021 | UQ13: =UB5&"19" -> КОЛ07019 | UR13: =UB5&"51" -> КОЛ07051 | US13: =UB5&"23" -> КОЛ07023
A14: 037 | B14: 01 | C14: РОССИЙСКАЯ ФЕДЕРАЦИЯ
A15: 037 | B15: 01 | C15: резерв
A16: 030 | B16: 02 | C16: ЦЕНТРАЛЬНЫЙ Ф.О.
A17: 14000000000 | B17: 03 | C17: Белгородская область | F17: 5033296200 | I17: 80189873 | J17: 63350000 | K17: 16839873 | L17: 63350000 | M17: 6500.37 | O17: 80189873 | P17: 63350000 | R17: 16839873 | S17: 21 | T17: 6500.37 | V17: 63350000 | X17: 63350000 | Y17: 63350000 | AA17: 2.7730886e+08 | AB17: 219074000 | AC17: 58234861 | AD17: 219074000 | AG17: 2.7730886e+08 | AH17: 219074000 | AJ17: 58234861 | AK17: 21 | AN17: 219074000 | AP17: 219074000 | AQ17: 219074000 | AS17: 1.9389387e+09 | AT17: 1531761600 | AU17: 4.0717713e+08 | AV17: 1531761600 | AY17: 1.9389387e+09 | AZ17: 1531761600 | BB17: 4.0717713e+08 | BC17: 21 | BF17: 1531761600 | BH17: 1531761600 | BI17: 1531761600 | BK17: 2.5547105e+09 | BL17: 2426975000 | BM17: 1.2773553e+08 | BN17: 2426975000 | BQ17: 2.5547105e+09 | BR17: 2426975000 | BT17: 1.2773553e+08 | BU17: 5 | BX17: 2426975000 | BZ17: 2426975000 | CA17: 2426975000 | CC17: 1.0340468e+08 | CD17: 81689700 | CE17: 21714984 | CF17: 81689700 | CI17: 1.0340468e+08 | CJ17: 81689700 | CL17: 21714984 | CM17: 21 | CP17: 81689700 | CR17: 81689700 | CS17: 81689700 | DM17: 5.5679028e+08 | DN17: 556734600 | DO17: 55679.03 | DP17: 556734600 | DS17: 5.5679028e+08 | DT17: 556734600 | DV17: 55679.03 | DW17: 0.01 | DZ17: 556734600 | EB17: 556734600 | EC17: 556734600 | EE17: 99067000 | EF17: 95104300 | EG17: 3962700 | EH17: 95104300 | EK17: 99067000 | EL17: 95104300 | EN17: 3962700 | EO17: 4.00002 | ER17: 95104300 | ET17: 95104300 | EU17: 95104300 | EW17: 49996582 | EX17: 39497300 | EY17: 10499282 | EZ17: 39497300 | FC17: 49996582 | FD17: 39497300 | FF17: 10499282 | FG17: 21 | FJ17: 39497300 | FL17: 39497300 | FM17: 39497300 | GG17: 23570000 | GH17: 18620300 | GI17: 4949700 | GJ17: 18620300 | GM17: 23570000 | GN17: 18620300 | GP17: 4949700 | GQ17: 21 | GT17: 18620300 | GV17: 18620300 | GW17: 18620300 | NE17: 619493.68 | NF17: 489400 | NG17: 130093.68 | NH17: 489400 | NK17: 619493.68 | NL17: 489400 | NN17: 130093.68 | NO17: 21 | NR17: 489400 | NT17: 489400 | NU17: 489400 | RM17: 1800191.2 | RT17: 1800191.2 | RU17: 0
A18: 15000000000 | B18: 04 | C18: Брянская область | F18: 10479326700 | I18: 1.9217554e+08 | J18: 176801500 | K18: 15374043 | L18: 176801500 | M18: 879553.12 | O18: 1.9217554e+08 | P18: 176801500 | R18: 15374043 | S18: 8 | T18: 879553.12 | V18: 176801500 | X18: 176801500 | Y18: 176801500 | AA18: 1.1243859e+08 | AB18: 103443500 | AC18: 8995087 | AD18: 103443500 | AE18: 51665.68 | AG18: 1.1243859e+08 | AH18: 103443500 | AJ18: 8995087 | AK18: 8 | AL18: 51665.68 | AN18: 103443500 | AP18: 103443500 | AQ18: 103443500 | AS18: 1.8173923e+09 | AT18: 1672000900 | AU18: 1.4539138e+08 | AV18: 1672000900 | AW18: 4674123 | AY18: 1.8173923e+09 | AZ18: 1672000900 | BB18: 1.4539138e+08 | BC18: 8 | BD18: 4674031 | BE18: 92 | BF18: 1672000900 | BH18: 1672000900 | BI18: 1672000900 | BK18: 8501299986 | BL18: 8270300000 | BM18: 230999986 | BN18: 8270300000 | BQ18: 8501299986 | BR18: 8270300000 | BT18: 230999986 | BU18: 2.71723 | BX18: 8270300000 | BZ18: 8270300000 | CA18: 8270300000 | CC18: 1.4737946e+08 | CD18: 135589100 | CE18: 11790357 | CF18: 135589100 | CG18: 644000 | CI18: 1.4737946e+08 | CJ18: 135589100 | CL18: 11790357 | CM18: 8 | CN18: 644000 | CP18: 135589100 | CR18: 135589100 | CS18: 135589100 | DM18: 18661500 | DN18: 14661500 | DO18: 4000000 | DP18: 14516158 | DS18: 18476505 | DT18: 14516158 | DV18: 3960347.2 | DW18: 21.4345 | DZ18: 14516158 | EB18: 14661500 | EC18: 14661500 | EE18: 33988283 | EF18: 33648400 | EG18: 339882.83 | EH18: 33648400 | EK18: 33988283 | EL18: 33648400 | EN18: 339882.83 | EO18: 1 | ER18: 33648400 | ET18: 33648400 | EU18: 33648400 | EW18: 66900868 | EX18: 49634500 | EY18: 17266368 | EZ18: 49634500 | FA18: 2292519.2 | FC18: 66900868 | FD18: 49634500 | FF18: 17266368 | FG18: 25.80889 | FH18: 2292519.2 | FJ18: 49634500 | FL18: 49634500 | FM18: 49634500 | FS18: 268728.92 | FZ18: 268728.92 | GG18: 24641957 | GH18: 22670600 | GI18: 1971356.5 | GJ18: 22460381 | GM18: 24413457 | GN18: 22460381 | GP18: 1953076.6 | GQ18: 8 | GT18: 22460381 | GV18: 22670600 | GW18: 22670600 | NE18: 626847.83 | NF18: 576700 | NG18: 50147.83 | NH18: 576700 | NK18: 626847.83 | NL18: 576700 | NN18: 50147.83 | NO18: 8 | NR18: 576700 | NT18: 576700 | NU18: 576700 | OS18: 1396668.1 | OZ18: 1396668.1
A19: 17000000000 | B19: 05 | C19: Владимирская область | F19: 890136300 | I19: 69712600 | J19: 62044200 | K19: 7668400 | L19: 62044200 | M19: 156964.61 | O19: 69712600 | P19: 62044200 | R19: 7668400 | S19: 11.00002 | T19: 156964.61 | V19: 62044200 | X19: 62044200 | Y19: 62044200 | AA19: 251097900 | AB19: 223477100 | AC19: 27620800 | AD19: 223477100 | AE19: 237989.42 | AG19: 251097900 | AH19: 223477100 | AJ19: 27620800 | AK19: 11.00001 | AL19: 237989.42 | AN19: 223477100 | AP19: 223477100 | AQ19: 223477100 | AS19: 301028400 | AT19: 267915200 | AU19: 33113200 | AV19: 267915200 | AW19: 14028877 | AY19: 301028400 | AZ19: 267915200 | BB19: 33113200 | BC19: 11.00003 | BD19: 14028877 | BF19: 267915200 | BH19: 267915200 | BI19: 267915200 | BK19: 194526316 | BL19: 184800000 | BM19: 9726316 | BN19: 184800000 | BQ19: 194526316 | BR19: 184800000 | BT19: 9726316 | BU19: 5 | BX19: 184800000 | BZ19: 184800000 | CA19: 184800000 | CC19: 53960000 | CD19: 37772000 | CE19: 16188000 | CF19: 37772000 | CI19: 53960000 | CJ19: 37772000 | CL19: 16188000 | CM19: 30 | CP19: 37772000 | CR19: 37772000 | CS19: 37772000 | EE19: 49096600 | EF19: 48114600 | EG19: 982000 | EH19: 48114600 | EK19: 49096600 | EL19: 48114600 | EN19: 982000 | EO19: 2.00014 | ER19: 48114600 | ET19: 48114600 | EU19: 48114600 | EW19: 18562580 | EX19: 16520700 | EY19: 2041880 | EZ19: 16520700 | FC19: 18562580 | FD19: 16520700 | FF19: 2041880 | FG19: 10.99998 | FJ19: 16520700 | FL19: 16520700 | FM19: 16520700 | GG19: 46416498 | GH19: 41310400 | GI19: 5106098 | GJ19: 41310396 | GM19: 46416422 | GN19: 41310332 | GP19: 5106089.6 | GQ19: 11.00061 | GS19: 64.07 | GT19: 41310396 | GV19: 41310400 | GW19: 41310400 | JA19: 3231685 | JB19: 2876200 | JC19: 355485 | JD19: 2876200 | JG19: 3231685 | JH19: 2876200 | JJ19: 355485 | JK19: 10.99999 | JN19: 2876200 | JP19: 2876200 | JQ19: 2876200 | KK19: 2355280 | KL19: 2096200 | KM19: 259080 | KN19: 2096200 | KQ19: 2355280 | KR19: 2096200 | KT19: 259080 | KU19: 10.99997 | KX19: 2096200 | KZ19: 2096200 | LA19: 2096200 | NE19: 3606500 | NF19: 3209700 | NG19: 396800 | NH19: 3209700 | NK19: 3606500 | NL19: 3209700 | NN19: 396800 | NO19: 11.00236 | NR19: 3209700 | NT19: 3209700 | NU19: 3209700
A20: 20000000000 | B20: 06 | C20: Воронежская область | F20: 6250239200 | I20: 511517500 | J20: 281789800 | K20: 229727700 | L20: 281789800 | M20: 196185.48 | O20: 511517500 | P20: 281789800 | R20: 229727700 | S20: 44.91101 | T20: 196185.48 | V20: 281789800 | X20: 281789800 | Y20: 281789800 | AA20: 356177800 | AB20: 302751100 | AC20: 53426700 | AD20: 302751100 | AE20: 5928008.8 | AG20: 356177800 | AH20: 302751100 | AJ20: 53426700 | AK20: 15.00001 | AL20: 5928008.8 | AN20: 302751100 | AP20: 302751100 | AQ20: 302751100 | AS20: 2351591000 | AT20: 1998852300 | AU20: 352738700 | AV20: 1.9988179e+09 | AW20: 48007953 | AY20: 2.3515506e+09 | AZ20: 1.9988179e+09 | BB20: 3.5273264e+08 | BC20: 15 | BD20: 48007953 | BE20: 1.39 | BF20: 1.9988179e+09 | BH20: 1998852300 | BI20: 1998852300 | BK20: 3.1192638e+09 | BL20: 2250000000 | BM20: 8.6926385e+08 | BN20: 2250000000 | BO20: 35847.7 | BQ20: 3.1192638e+09 | BR20: 2250000000 | BT20: 8.6926385e+08 | BU20: 27.8676 | BV20: 35847.7 | BX20: 2250000000 | BZ20: 2250000000 | CA20: 2250000000 | CC20: 131158900 | CD20: 81158900 | CE20: 50000000 | CF20: 81158900 | CI20: 131158900 | CJ20: 81158900 | CL20: 50000000 | CM20: 38.1217 | CP20: 81158900 | CR20: 81158900 | CS20: 81158900 | DM20: 1.2734923e+09 | DN20: 1211953800 | DO20: 61538502 | DP20: 1211953800 | DS20: 1.2734923e+09 | DT20: 1211953800 | DV20: 61538502 | DW20: 4.83226 | DZ20: 1211953800 | EB20: 1211953800 | EC20: 1211953800 | EE20: 49198061 | EF20: 48214100 | EG20: 983961.22 | EH20: 48214100 | EK20: 49198061 | EL20: 48214100 | EN20: 983961.22 | EO20: 2 | ER20: 48214100 | ET20: 48214100 | EU20: 48214100 | EW20: 73313000 | EX20: 49984200 | EY20: 23328800 | EZ20: 49968216 | FC20: 73289556 | FD20: 49968216 | FF20: 23321340 | FG20: 31.82082 | FJ20: 49968216 | FL20: 49984200 | FM20: 49984200 | GG20: 77965100 | GH20: 18668900 | GI20: 59296200 | GJ20: 18668900 | GM20: 77965098 | GN20: 18668900 | GP20: 59296199 | GQ20: 76.0548 | GT20: 18668900 | GV20: 18668900 | GW20: 18668900 | JA20: 7800000 | JB20: 4762400 | JC20: 3037600 | JD20: 4762400 | JG20: 7800000 | JH20: 4762400 | JJ20: 3037600 | JK20: 38.94359 | JN20: 4762400 | JP20: 4762400 | JQ20: 4762400 | KK20: 4620700 | KL20: 1462800 | KM20: 3157900 | KN20: 1462800 | KQ20: 4620700 | KR20: 1462800 | KT20: 3157900 | KU20: 68.34246 | KX20: 1462800 | KZ20: 1462800 | LA20: 1462800 | NE20: 1175900 | NF20: 640900 | NG20: 535000 | NH20: 640900 | NK20: 1175900 | NL20: 640900 | NN20: 535000 | NO20: 45.49707 | NR20: 640900 | NT20: 640900 | NU20: 640900 | OS20: 7676022.2 | OZ20: 7676022.2 | RM20: 1089397.5 | RT20: 1089397.5
