Workbook
Name date: data_1!$D$2
Name Print_Area: '1.4 (1.4.1-1.4.2)'!$A$2:$BG$109
Name Print_Titles: '1.4 (1.4.1-1.4.2)'!$B:$C,'1.4 (1.4.1-1.4.2)'!$7:$12
Name ЕдиницаВыбор: #REF!
Name ЕдиницаДоведение: #REF!
Name ЕдиницаМатрица: #REF!
Name КОЛ04904: data_1!$AAH$14:$AAH$108
Name КОЛ04905: data_1!$AAI$14:$AAI$108
Name КОЛ04906: data_1!$AAJ$14:$AAJ$108
Name КОЛ04907: data_1!$AAK$14:$AAK$108
Name КОЛ04908: data_1!$AAL$14:$AAL$108
Name КОЛ04909: data_1!$AAM$14:$AAM$108
Name КОЛ04910: data_1!$AAO$14:$AAO$108
Name КОЛ04911: data_1!$AAP$14:$AAP$108
Name КОЛ04912: data_1!$AAQ$14:$AAQ$108
Name КОЛ04913: data_1!$AAR$14:$AAR$108
Name КОЛ04914: data_1!$AAS$14:$AAS$108
Name КОЛ04915: data_1!$AAT$14:$AAT$108
Name КОЛ04916: data_1!$AAU$14:$AAU$108
Name КОЛ04919: data_1!$AAW$14:$AAW$108
Name КОЛ04921: data_1!$AAV$14:$AAV$108
Name КОЛ04923: data_1!$AAY$14:$AAY$108
Name КОЛ04951: data_1!$AAX$14:$AAX$108
Name КОЛ04952: data_1!$AAN$14:$AAN$108
Name КОЛ05104: data_1!$ABR$14:$ABR$108
Name КОЛ05105: data_1!$ABS$14:$ABS$108
Name КОЛ05106: data_1!$ABT$14:$ABT$108
Name КОЛ05107: data_1!$ABU$14:$ABU$108
Name КОЛ05108: data_1!$ABV$14:$ABV$108
Name КОЛ05109: data_1!$ABW$14:$ABW$108
Name КОЛ05110: data_1!$ABY$14:$ABY$108
Name КОЛ05111: data_1!$ABZ$14:$ABZ$108
Name КОЛ05112: data_1!$ACA$14:$ACA$108
Name КОЛ05113: data_1!$ACB$14:$ACB$108
Name КОЛ05114: data_1!$ACC$14:$ACC$108
Name КОЛ05115: data_1!$ACD$14:$ACD$108
Name КОЛ05116: data_1!$ACE$14:$ACE$108
Name КОЛ05119: data_1!$ACG$14:$ACG$108
Name КОЛ05121: data_1!$ACF$14:$ACF$108
Name КОЛ05123: data_1!$ACI$14:$ACI$108
Name КОЛ05151: data_1!$ACH$14:$ACH$108
Name КОЛ05152: data_1!$ABX$14:$ABX$108
Name КОЛ05204: data_1!$ADB$14:$ADB$108
Name КОЛ05205: data_1!$ADC$14:$ADC$108
Name КОЛ05206: data_1!$ADD$14:$ADD$108
Name КОЛ05207: data_1!$ADE$14:$ADE$108
Name КОЛ05208: data_1!$ADF$14:$ADF$108
Name КОЛ05209: data_1!$ADG$14:$ADG$108
Name КОЛ05210: data_1!$ADI$14:$ADI$108
Name КОЛ05211: data_1!$ADJ$14:$ADJ$108
Name КОЛ05212: data_1!$ADK$14:$ADK$108
Name КОЛ05213: data_1!$ADL$14:$ADL$108
Name КОЛ05214: data_1!$ADM$14:$ADM$108
Name КОЛ05215: data_1!$ADN$14:$ADN$108
Name КОЛ05216: data_1!$ADO$14:$ADO$108
Name КОЛ05219: data_1!$ADQ$14:$ADQ$108
Name КОЛ05221: data_1!$ADP$14:$ADP$108
Name КОЛ05223: data_1!$ADS$14:$ADS$108
Name КОЛ05251: data_1!$ADR$14:$ADR$108
Name КОЛ05252: data_1!$ADH$14:$ADH$108

Sheet data_1
C2: по состояню на | D2: Декабрь 2016 г.
H5: 16 | Z5: 15 | AR5: 17 | BJ5: 18 | CB5: 59 | CT5: 19 | DL5: 66 | ED5: 67 | EV5: 80 | FN5: 79 | GF5: 81 | GX5: 22 | HP5: 77 | IH5: 23 | IZ5: 78 | JR5: 62 | KJ5: 25 | LB5: 26 | LT5: 70 | ML5: 31 | ND5: 32 | NV5: 33 | ON5: 34 | PF5: 35 | PX5: 36 | QP5: 37 | RH5: 40 | RZ5: 41 | SR5: 43 | TJ5: 44 | UB5: 45 | UT5: 72 | VL5: 73 | WD5: 74 | WV5: 71 | XN5: 75 | YF5: 76 | YX5: 61 | ZP5: 49 | AAH5: КОЛ049 | AAZ5: 51 | ABR5: КОЛ051 | ACJ5: 52 | ADB5: КОЛ052 | ADT5: 53 | AEL5: КОЛ053 | AFD5: 54 | AFV5: КОЛ054 | AGN5: 55 | AHF5: КОЛ055 | AHX5: 60 | AIP5: КОЛ060 | AJH5: 57 | AJZ5: 58 | AKR5: 69 | ALJ5: 82 | AMB5: 83 | AMT5: 46
H6: 1.1.2. - Субсидии на возмещение части процентной ставки по краткосрочным кредитам (займам) на развитие животноводства, переработки и реализации продукции животноводства, КБК: 04 05 2520650470 521 | Z6: 1.1.1. - Субсидии на возмещение части процентной ставки по краткосрочным кредитам (займам) на развитие растениеводства, переработки и реализации продукции растениеводства, КБК: 04 05 2510450380 521 | AR6: 1.1.3. - Субсидии на возмещение части процентной ставки по инвестиционным кредитам (займам) на развитие растениеводства, переработки и развития инфраструктуры и логистического обеспечения рынков продукции растениеводства, КБК: 04 05 2510450390 521 | BJ6: 1.1.4. - Субсидии на возмещение части процентной ставки по инвестиционным кредитам (займам) на развитие животноводства, переработки и развития инфраструктуры и логистического обеспечения рынков продукции животноводства, КБК: 04 05 2520650480 521 | CB6: 1.1.5. - Субсидии на возмещение части процентной ставки по инвестиционным кредитам на строительство и реконструкцию объектов мясного скотоводства, КБК: 04 05 2530350520 521 | CT6: 1.1.6. - Cубсидии на возмещение части процентной ставки по долгосрочным, среднесрочным и краткосрочным кредитам, взятым малыми формами хозяйствования, КБК: 04 05 2540150550 521 | DL6: 1.1.7. - Cубсидии на возмещение части процентной ставки по инвестиционным кредитам (займам) на строительство и реконструкцию объектов для молочного скотоводства, КБК: 04 05 25Б0254440 521 | ED6: 1.1.8. - Субсидии на возмещение части процентной ставки по краткосрочным кредитам (займам) на развитие молочного скотоводства, КБК: 04 05 25Б0254430 521 | EV6: 1.1.9. - Субсидии на возмещение части процентной ставки по краткосрочным кредитам (займам) на переработку продукции растениеводства и животноводства в области развития оптово-распределительных центров, КБК: 04 05 25Д0154500 521 | FN6: 1.1.10 - Субсидии на возмещение части процентной ставки по краткосрочным кредитам (займам) на развитие селекционно-генетических и селекционно-семеноводческих центров в подотраслях животноводства и растениеводства, КБК: 04 05 25Г0654480 521 | GF6: 1.1.11 - Субсидии на возмещение части процентной ставки по инвестиционным кредитам (займам) на развитие оптово-распределительных центров, производства и товаропроводящей инфраструктуры системы социального питания, КБК: 04 05 25Д0154510 521 | GX6: 1.2.1 - Субсидии на поддержку племенного животноводства, КБК: 04 05 25Г0250420 521 | HP6: 1.2.2 - Субсидии на поддержку племенного крупного рогатого скота мясных пород и их помесей, КБК: 04 05 2530154530 521 | IH6: 1.2.3 - Субсидии на поддержку племенного крупного рогатого скота мясного направления, КБК: 04 05 25Г0450500 521 | IZ6: 1.2.4 - Субсидии на поддержку племенного крупного рогатого скота молочного направления, КБК: 04 05 25Г0354460 521 | JR6: 1.2.5. - Субсидии на 1 кг реализованного товарного молока (подпрограмма молочного скотоводства), КБК: 04 05 25Б0150430 521 | KJ6: 1.2.6. - Субсидии на возмещение части затрат по наращиванию поголовья северных оленей, маралов и мясных табунных лошадей, КБК: 04 05 2520250450 521 | LB6: 1.2.7. - Субсидии на возмещение части затрат по наращиванию маточного поголовья овец и коз, КБК: 04 05 2520150440 521 | LT6: 1.2.8. - Субсидии бюджетам на поддержку производства и реализации тонкорунной и полутонкорунной шерсти, КБК: 04 05 2520954360 521 | ML6: 1.3.1. - Субсидии на поддержку элитного семеноводства, КБК: 04 05 25Г0150310 521 | ND6: 1.3.2. - Возмещение части затрат на закладку и уход за виноградниками, КБК: 04 05 2510150320 521 | NV6: 1.3.3. - Возмещение части затрат на раскорчевку выбывших из эксплуатации старых садов и рекультивацию раскорчеванных площадей, КБК: 04 05 2510150330 521 | ON6: 1.3.4. - Возмещение части затрат на закладку и уход за многолетними плодовыми и ягодными насаждениями, КБК: 04 05 2510150340 521 | PF6: 1.3.5. - Субсидии на возмещение части затрат на приобретение семян с учетом доставки в районы Крайнего Севера и приравненные к ним местности, КБК: 04 05 2510350360 521 | PX6: 1.3.6. - Субсидии на производство продукции растениеводства на низкопродуктивной пашне в районах Крайнего Севера и приравненных к ним местностях, КБК: 04 05 2510350370 521 | QP6: 1.3.7. - Субсидии на оказание несвязанной поддержки сельскохозяйственным товаропроизводителям в области растениеводства, КБК: 04 05 2510750410 521 | RH6: 1.4. - Субсидии на возмещение части затрат сельскохозяйственных товаропроизводителей на уплату страховой премии, начисленной по договору сельскохозяйственного страхования в области растениеводства, КБК: 04 05 2510550400 521 | RZ6: 1.5. - Субсидии на возмещение части затрат сельскохозяйственных товаропроизводителей на уплату страховой премии, начисленной по договору сельскохозяйственного страхования в области животноводства, КБК: 04 05 2520750490 521 | SR6: 1.6. - Субсидии на поддержку экономически значимых региональных программ в области растениеводства, КБК: 04 05 2510150350 521 | TJ6: 1.7. - Субсидии на поддержку экономически значимых региональных программ в области животноводства, КБК: 04 05 2520550460 521 | UB6: 1.8. - Субсидии на поддержку экономически значимых региональных программ по развитию мясного скотоводства, КБК: 04 05 2530250510 521 | UT6: 1.9. - Субсидии на возмещение части прямых понесенных затрат на создание и модернизацию объектов тепличных комплексов, а также на приобретение техники и оборудования на цели предоставления субсидий, КБК: 04 05 2590254410 521 | VL6: 1.10. - Субсидии на возмещение части прямых понесенных затрат на создание и модернизацию объектов плодохранилищ, а также на приобретение техники и оборудования на цели предоставления субсидий, КБК: 04 05 2510154370 521 | WD6: 1.11. - Субсидии на возмещение части прямых понесенных затрат на создание и модернизацию объектов картофелехранилищ и овощехранилищ, а также на приобретение техники и оборудования на цели предоставления субсидий, КБК: 04 05 2590154400 521 | WV6: 1.12. - Субсидии на возмещение части прямых понесенных затрат на создание и модернизацию объектов животноводческих комплексов молочного направления (молочных ферм), а также на приобретение техники и оборудования на цели предоставления субсидий, КБК: 04 05 25Б0154420 521 | XN6: 1.13. - Субсидии на возмещение части прямых понесенных затрат на создание и модернизацию объектов селекционно-генетических центров в животноводстве и селекционно-семеноводческих центров в растениеводстве, а также на приобретение техники и оборудования на цели предоставления субсидий, КБК: 04 05 25Г0554470 521 | YF6: 1.14 - Субсидии на возмещение части прямых понесенных затрат на создание оптово-распределительных центров, а также на приобретение техники и оборудования на цели предоставления субсидий, КБК: 04 05 25Д0254520 521 | YX6: 3 - ФЦП "Развитие мелиорации земель сельскохозяйственного назначения России на 2014 - 2020 годы" , КБК: 04 05 2580050760 521 | ZP6: 4.1. - Субсидии на обеспечение жильем граждан, проживающих и работающих в сельской местности, и на обеспечение жильем молодых семей и молодых специалистов, проживающих и работающих в сельской местности, КБК: 10 03 2570050180 521 | AAH6: 4.1. - Субсидии на обеспечение жильем граждан, проживающих и работающих в сельской местности, и на обеспечение жильем молодых семей и молодых специалистов, проживающих и работающих в сельской местности, КБК: 10 03 0005898 521 | AAZ6: 4.2. - Софинансирование объектов капитального строительства госсобственности субъектов Российской Федерации (собственности муниципальных образований) всего, в том числе:, КБК: 05 02 2570050180 522 | ABR6: 4.2. - Софинансирование объектов капитального строительства госсобственности субъектов Российской Федерации (собственности муниципальных образований) всего, в том числе:, КБК: 05 02 0000058980 522 | ACJ6: 4.2. - Софинансирование объектов капитального строительства госсобственности субъектов Российской Федерации (собственности муниципальных образований) всего, в том числе:, КБК: 07 02 2570050180 522 | ADB6: 4.2. - Софинансирование объектов капитального строительства госсобственности субъектов Российской Федерации (собственности муниципальных образований) всего, в том числе:, КБК: 07 02 0000058980 522 | ADT6: 4.2. - Софинансирование объектов капитального строительства госсобственности субъектов Российской Федерации (собственности муниципальных образований) всего, в том числе:, КБК: 09 02 2570050180 522 | AEL6: 4.2. - Софинансирование объектов капитального строительства госсобственности субъектов Российской Федерации (собственности муниципальных образований) всего, в том числе:, КБК: 09 02 0000058980 522 | AFD6: 4.2. - Софинансирование объектов капитального строительства госсобственности субъектов Российской Федерации (собственности муниципальных образований) всего, в том числе:, КБК: 11 01 2570050180 522 | AFV6: 4.2. - Софинансирование объектов капитального строительства госсобственности субъектов Российской Федерации (собственности муниципальных образований) всего, в том числе:, КБК: 11 01 0000058980 522 | AGN6: 4.3. - Субсидии на комплексную компактную застройку, КБК: 04 05 2570050180 522 | AHF6: 4.3. - Субсидии на комплексную компактную застройку, КБК: 04 05 0000058980 522 | AHX6: 4.4. - Субсидии на грантовую поддержку местных инициатив граждан, проживающих в сельской местности, КБК: 04 05 2570050180 521 | AIP6: 4.4. - Субсидии на грантовую поддержку местных инициатив граждан, проживающих в сельской местности, КБК: 09 02 0000058980 521 | AJH6: 5 - Субсидии на поддержку начинающих фермеров, КБК: 04 05 2540350530 521 | AJZ6: 6 - Субсидии на развитие семейных животноводческих ферм, КБК: 04 05 2540450540 521 | AKR6: 7 - Субсидии на грантовую поддержку сельскохозяйственных потребительских кооперативов для развития материально-технической базы, КБК: 04 05 2540554380 500 | ALJ6: 8 - Прочие субсидии ( оформление в собственность используемых ими земельных участков из земель сельскохозяйственного назначения, консультационная помощь, лен и конопля, защита растений, средства химизации, корма и др.), КБК: 04 05 0000058980 521 | AMB6: 1.3.8. - Субсидии на оказание несвязанной поддержки сельскохозяйственным товаропроизводителям в области развития производства семенного картофеля и овощей открытого грунта, КБК: 04 05 2590154390 521 | AMT6: 2 -Возмещение части затрат крестьянских (фермерских) хозяйств, включая индивидуальных предпринимателей, при оформлении в собственность используемых ими земельных участков из земель сельскохозяйственного назначения (только по подтвержденным остаткам) , КБК: 04 05 2540250560 521
